Workbook

Sheet 2021
C1: Identificador | D1: +1+2+4+32+22-0-0-0-0-0-0-0-0 | E1: 0-+1-0-0-0-0-0-0-0 | F1: 0-+1-+1-0-0-0-0-0-0 | G1: 0-+1-+2-0-0-0-0-0-0 | H1: 0-+2-0-0-0-0-0-0-0 | I1: 32-3-0-0-0-0-0-0-0 | J1: 1-0-0-0-0-0-0-0-0 | K1: 1-1-0-0-0-0-0-0-0 | L1: 0-0-0-0-0-+200-0-0-0 | M1: +1-0-+2-0-0-0-0-0-0 | N1: 0-0-0-0-0-+100-0-0-0 | O1: 1-0-1-0-0-0-0-0-0 | P1: 2-0-0-0-0-0-0-0-0 | Q1: 2-1-0-0-0-0-0-0-0 | R1: 2-1-1-0-0-0-0-0-0 | S1: 2-1-2-0-0-0-0-0-0 | T1: +4-0-0-0-0-0-0-0-0 | U1: 4-0-1-0-0-0-0-0-0 | V1: 4-0-2-0-0-0-0-0-0 | W1: 4-0-0-1-0-0-0-0-0 | X1: 4-1-0-1-0-0-0-0-0 | Y1: 4-1-1-1-0-0-0-0-0 | Z1: 4-1-2-1-0-0-0-0-0 | AA1: +32-3-0-0-0-0-0-0-0 | AB1: 1-1-1-1-1-200-1-1- | AC1: 1-1-1-1-2-200-1-1- | AD1: 1-1-2-1-6-0-1-1- | AE1: 1-1-1-1-7-200-1-2- | AF1: 1-1-2-1-9-0-1-3- | AG1: 1-1-2-1-12-0-1-3- | AH1: 1-1-2-1-13-0-1-3- | AI1: 1-1-1-1-23-200-1-1- | AJ1: 1-1-1-2-30-200-7-3- | AK1: 1-1-1-2-39-200-7-2- | AL1: 1-1-2-2-42-0-7-3- | AM1: 1-2-1-1-43-100-1-2- | AN1: 1-1-1-2-49-200-7-1- | AO1: 1-1-1-1-51-200-6-3- | AP1: 1-1-1-1-52-200-6-3- | AQ1: 1-1-1-1-53-200-6-3- | AR1: 1-1-1-1-54-200-6-3- | AS1: 1-1-1-1-55-200-6-3- | AT1: 1-1-2-1-56-0-6-3- | AU1: 1-1-2-1-57-0-6-3- | AV1: 1-1-1-1-58-200-1-3- | AW1: 1-1-2-1-59-0-1-1- | AX1: 1-1-1-1-60-200-1-1- | AY1: 1-1-1-1-62-200-1-1- | AZ1: 1-1-1-1-63-200-1-1- | BA1: 1-1-2-1-64-0-1-1- | BB1: 1-1-1-1-65-200-1-1- | BC1: 1-1-2-1-66-0-1-1- | BD1: 2-1-1-4-11-0-1-1- | BE1: 2-1-1-4-37-0-1-2- | BF1: 2-1-2-4-42-0-2-0- | BG1: 2-1-1-4-48-0-2-0- | BH1: 2-1-1-4-49-0-2-0- | BI1: 4-1-1-1-8-0-1-1- | BJ1: 4-1-1-1-26-0-1-2- | BK1: 4-1-2-1-31-0-1-3- | BL1: 4-1-1-1-46-0-6-1- | BM1: 4-1-1-1-108-0-1-2- | BN1: 4-1-1-1-117-0-0-3- | BO1: 4-1-2-1-118-0-0-3- | BP1: 4-1-2-1-120-0-0-3- | BQ1: 4-1-1-1-121-0-0-3- | BR1: 4-1-2-1-122-0-0-3- | BS1: 4-1-2-1-123-0-0-3- | BT1: 32-3-1-1-1-0-1-1-300 | BU1: 32-3-1-1-2-0-1-3-300 | BV1: 32-3-1-1-3-0-1-2-300 | BW1: 32-3-1-1-4-0-1-2-300 | BX1: 32-3-1-1-5-0-1-3-300
C2: Tipo | D2: +1+2+4+32+22 | E2: 0 | F2: 0 | G2: 0 | H2: 0 | I2: 32 | J2: 1 | K2: 1 | L2: 0 | M2: +1 | N2: 0 | O2: 1 | P2: 2 | Q2: 2 | R2: 2 | S2: 2 | T2: +4 | U2: 4 | V2: 4 | W2: 4 | X2: 4 | Y2: 4 | Z2: 4 | AA2: +32 | AB2: 1 | AC2: 1 | AD2: 1 | AE2: 1 | AF2: 1 | AG2: 1 | AH2: 1 | AI2: 1 | AJ2: 1 | AK2: 1 | AL2: 1 | AM2: 1 | AN2: 1 | AO2: 1 | AP2: 1 | AQ2: 1 | AR2: 1 | AS2: 1 | AT2: 1 | AU2: 1 | AV2: 1 | AW2: 1 | AX2: 1 | AY2: 1 | AZ2: 1 | BA2: 1 | BB2: 1 | BC2: 1 | BD2: 2 | BE2: 2 | BF2: 2 | BG2: 2 | BH2: 2 | BI2: 4 | BJ2: 4 | BK2: 4 | BL2: 4 | BM2: 4 | BN2: 4 | BO2: 4 | BP2: 4 | BQ2: 4 | BR2: 4 | BS2: 4 | BT2: 32 | BU2: 32 | BV2: 32 | BW2: 32 | BX2: 32
C3: Clase | D3: 0 | E3: +1 | F3: +1 | G3: +1 | H3: +2 | I3: 3 | J3: 0 | K3: 1 | L3: 0 | M3: 0 | N3: 0 | O3: 0 | P3: 0 | Q3: 1 | R3: 1 | S3: 1 | T3: 0 | U3: 0 | V3: 0 | W3: 0 | X3: 1 | Y3: 1 | Z3: 1 | AA3: 3 | AB3: 1 | AC3: 1 | AD3: 1 | AE3: 1 | AF3: 1 | AG3: 1 | AH3: 1 | AI3: 1 | AJ3: 1 | AK3: 1 | AL3: 1 | AM3: 2 | AN3: 1 | AO3: 1 | AP3: 1 | AQ3: 1 | AR3: 1 | AS3: 1 | AT3: 1 | AU3: 1 | AV3: 1 | AW3: 1 | AX3: 1 | AY3: 1 | AZ3: 1 | BA3: 1 | BB3: 1 | BC3: 1 | BD3: 1 | BE3: 1 | BF3: 1 | BG3: 1 | BH3: 1 | BI3: 1 | BJ3: 1 | BK3: 1 | BL3: 1 | BM3: 1 | BN3: 1 | BO3: 1 | BP3: 1 | BQ3: 1 | BR3: 1 | BS3: 1 | BT3: 3 | BU3: 3 | BV3: 3 | BW3: 3 | BX3: 3
C4: Origen | D4: 0 | E4: 0 | F4: +1 | G4: +2 | H4: 0 | I4: 0 | J4: 0 | K4: 0 | L4: 0 | M4: +2 | N4: 0 | O4: 1 | P4: 0 | Q4: 0 | R4: 1 | S4: 2 | T4: 0 | U4: 1 | V4: 2 | W4: 0 | X4: 0 | Y4: 1 | Z4: 2 | AA4: 0 | AB4: 1 | AC4: 1 | AD4: 2 | AE4: 1 | AF4: 2 | AG4: 2 | AH4: 2 | AI4: 1 | AJ4: 1 | AK4: 1 | AL4: 2 | AM4: 1 | AN4: 1 | AO4: 1 | AP4: 1 | AQ4: 1 | AR4: 1 | AS4: 1 | AT4: 2 | AU4: 2 | AV4: 1 | AW4: 2 | AX4: 1 | AY4: 1 | AZ4: 1 | BA4: 2 | BB4: 1 | BC4: 2 | BD4: 1 | BE4: 1 | BF4: 2 | BG4: 1 | BH4: 1 | BI4: 1 | BJ4: 1 | BK4: 2 | BL4: 1 | BM4: 1 | BN4: 1 | BO4: 2 | BP4: 2 | BQ4: 1 | BR4: 2 | BS4: 2 | BT4: 1 | BU4: 1 | BV4: 1 | BW4: 1 | BX4: 1
C5: Categoría | D5: 0 | E5: 0 | F5: 0 | G5: 0 | H5: 0 | I5: 0 | J5: 0 | K5: 0 | L5: 0 | M5: 0 | N5: 0 | O5: 0 | P5: 0 | Q5: 0 | R5: 0 | S5: 0 | T5: 0 | U5: 0 | V5: 0 | W5: 1 | X5: 1 | Y5: 1 | Z5: 1 | AA5: 0 | AB5: 1 | AC5: 1 | AD5: 1 | AE5: 1 | AF5: 1 | AG5: 1 | AH5: 1 | AI5: 1 | AJ5: 2 | AK5: 2 | AL5: 2 | AM5: 1 | AN5: 2 | AO5: 1 | AP5: 1 | AQ5: 1 | AR5: 1 | AS5: 1 | AT5: 1 | AU5: 1 | AV5: 1 | AW5: 1 | AX5: 1 | AY5: 1 | AZ5: 1 | BA5: 1 | BB5: 1 | BC5: 1 | BD5: 4 | BE5: 4 | BF5: 4 | BG5: 4 | BH5: 4 | BI5: 1 | BJ5: 1 | BK5: 1 | BL5: 1 | BM5: 1 | BN5: 1 | BO5: 1 | BP5: 1 | BQ5: 1 | BR5: 1 | BS5: 1 | BT5: 1 | BU5: 1 | BV5: 1 | BW5: 1 | BX5: 1
C6: Código | D6: 0 | E6: 0 | F6: 0 | G6: 0 | H6: 0 | I6: 0 | J6: 0 | K6: 0 | L6: 0 | M6: 0 | N6: 0 | O6: 0 | P6: 0 | Q6: 0 | R6: 0 | S6: 0 | T6: 0 | U6: 0 | V6: 0 | W6: 0 | X6: 0 | Y6: 0 | Z6: 0 | AA6: 0 | AB6: 1 | AC6: 2 | AD6: 6 | AE6: 7 | AF6: 9 | AG6: 12 | AH6: 13 | AI6: 23 | AJ6: 30 | AK6: 39 | AL6: 42 | AM6: 43 | AN6: 49 | AO6: 51 | AP6: 52 | AQ6: 53 | AR6: 54 | AS6: 55 | AT6: 56 | AU6: 57 | AV6: 58 | AW6: 59 | AX6: 60 | AY6: 62 | AZ6: 63 | BA6: 64 | BB6: 65 | BC6: 66 | BD6: 11 | BE6: 37 | BF6: 42 | BG6: 48 | BH6: 49 | BI6: 8 | BJ6: 26 | BK6: 31 | BL6: 46 | BM6: 108 | BN6: 117 | BO6: 118 | BP6: 120 | BQ6: 121 | BR6: 122 | BS6: 123 | BT6: 1 | BU6: 2 | BV6: 3 | BW6: 4 | BX6: 5
C7: Gupo | D7: 0 | E7: 0 | F7: 0 | G7: 0 | H7: 0 | I7: 0 | J7: 0 | K7: 0 | L7: +200 | M7: 0 | N7: +100 | O7: 0 | P7: 0 | Q7: 0 | R7: 0 | S7: 0 | T7: 0 | U7: 0 | V7: 0 | W7: 0 | X7: 0 | Y7: 0 | Z7: 0 | AA7: 0 | AB7: 200 | AC7: 200 | AD7: 0 | AE7: 200 | AF7: 0 | AG7: 0 | AH7: 0 | AI7: 200 | AJ7: 200 | AK7: 200 | AL7: 0 | AM7: 100 | AN7: 200 | AO7: 200 | AP7: 200 | AQ7: 200 | AR7: 200 | AS7: 200 | AT7: 0 | AU7: 0 | AV7: 200 | AW7: 0 | AX7: 200 | AY7: 200 | AZ7: 200 | BA7: 0 | BB7: 200 | BC7: 0 | BD7: 0 | BE7: 0 | BF7: 0 | BG7: 0 | BH7: 0 | BI7: 0 | BJ7: 0 | BK7: 0 | BL7: 0 | BM7: 0 | BN7: 0 | BO7: 0 | BP7: 0 | BQ7: 0 | BR7: 0 | BS7: 0 | BT7: 0 | BU7: 0 | BV7: 0 | BW7: 0 | BX7: 0
C8: Estado | D8: 0 | E8: 0 | F8: 0 | G8: 0 | H8: 0 | I8: 0 | J8: 0 | K8: 0 | L8: 0 | M8: 0 | N8: 0 | O8: 0 | P8: 0 | Q8: 0 | R8: 0 | S8: 0 | T8: 0 | U8: 0 | V8: 0 | W8: 0 | X8: 0 | Y8: 0 | Z8: 0 | AA8: 0 | AB8: 1 | AC8: 1 | AD8: 1 | AE8: 1 | AF8: 1 | AG8: 1 | AH8: 1 | AI8: 1 | AJ8: 7 | AK8: 7 | AL8: 7 | AM8: 1 | AN8: 7 | AO8: 6 | AP8: 6 | AQ8: 6 | AR8: 6 | AS8: 6 | AT8: 6 | AU8: 6 | AV8: 1 | AW8: 1 | AX8: 1 | AY8: 1 | AZ8: 1 | BA8: 1 | BB8: 1 | BC8: 1 | BD8: 1 | BE8: 1 | BF8: 2 | BG8: 2 | BH8: 2 | BI8: 1 | BJ8: 1 | BK8: 1 | BL8: 6 | BM8: 1 | BN8: 0 | BO8: 0 | BP8: 0 | BQ8: 0 | BR8: 0 | BS8: 0 | BT8: 1 | BU8: 1 | BV8: 1 | BW8: 1 | BX8: 1
C9: Delegatura | D9: 0 | E9: 0 | F9: 0 | G9: 0 | H9: 0 | I9: 0 | J9: 0 | K9: 0 | L9: 0 | M9: 0 | N9: 0 | O9: 0 | P9: 0 | Q9: 0 | R9: 0 | S9: 0 | T9: 0 | U9: 0 | V9: 0 | W9: 0 | X9: 0 | Y9: 0 | Z9: 0 | AA9: 0 | AB9: 1 | AC9: 1 | AD9: 1 | AE9: 2 | AF9: 3 | AG9: 3 | AH9: 3 | AI9: 1 | AJ9: 3 | AK9: 2 | AL9: 3 | AM9: 2 | AN9: 1 | AO9: 3 | AP9: 3 | AQ9: 3 | AR9: 3 | AS9: 3 | AT9: 3 | AU9: 3 | AV9: 3 | AW9: 1 | AX9: 1 | AY9: 1 | AZ9: 1 | BA9: 1 | BB9: 1 | BC9: 1 | BD9: 1 | BE9: 2 | BF9: 0 | BG9: 0 | BH9: 0 | BI9: 1 | BJ9: 2 | BK9: 3 | BL9: 1 | BM9: 2 | BN9: 3 | BO9: 3 | BP9: 3 | BQ9: 3 | BR9: 3 | BS9: 3 | BT9: 1 | BU9: 3 | BV9: 2 | BW9: 2 | BX9: 3
C10: Director Técnico | D10: 0 | E10: 0 | F10: 0 | G10: 0 | H10: 0 | I10: 0 | J10: 0 | K10: 0 | L10: 0 | M10: 0 | N10: 0 | O10: 0 | P10: 0 | Q10: 0 | R10: 0 | S10: 0 | T10: 0 | U10: 0 | V10: 0 | W10: 0 | X10: 0 | Y10: 0 | Z10: 0 | AA10: 0 | AB10: 0 | AC10: 0 | AD10: 0 | AE10: 0 | AF10: 0 | AG10: 0 | AH10: 0 | AI10: 0 | AJ10: 0 | AK10: 0 | AL10: 0 | AM10: 0 | AN10: 0 | AO10: 0 | AP10: 0 | AQ10: 0 | AR10: 0 | AS10: 0 | AT10: 0 | AU10: 0 | AV10: 0 | AW10: 0 | AX10: 0 | AY10: 0 | AZ10: 0 | BA10: 0 | BB10: 0 | BC10: 0 | BD10: 0 | BE10: 0 | BF10: 0 | BG10: 0 | BH10: 0 | BI10: 0 | BJ10: 0 | BK10: 0 | BL10: 0 | BM10: 0 | BN10: 0 | BO10: 0 | BP10: 0 | BQ10: 0 | BR10: 0 | BS10: 0 | BT10: 300 | BU10: 300 | BV10: 300 | BW10: 300 | BX10: 300
C11: Nombre de la entidad | D11: Total Entidades Establecimientos de crédito sin IOE'S | E11: Total Sector Privado | F11: Total Sector Privado Nacional | G11: Total Sector Privado Extranjero | H11: Total Sector Público | I11: Total Sector Cooperativas | J11: Total Bancos | K11: Bancos Privados | L11: Bancos Privados Nacionales | M11: Bancos Privados Extranjeros | N11: Bancos Públicos | O11: Bancos Nacionales | P11: Total CFIs | Q11: CFIs Privadas | R11: CFIs Privadas Nacionales | S11: CFIs Privadas Extranjeras | T11: Total CFs | U11: Total CFs Nacionales (Tradicionales+Leasing) | V11: Total CFs Extranjeras (Tradicionales+Leasing) | W11: Total CFs Tradicionales | X11: CFs Privadas | Y11: CFs Privadas Nacionales | Z11: CFs Privadas Extranjeras | AA11: Total Cooperativas | AB11: BANCO DE BOGOTA | AC11: BANCO POPULAR | AD11: ITAÚ CORPBANCA COLOMBIA S.A. | AE11: BANCOLOMBIA | AF11: CITIBANK-COLOMBIA | AG11: GNB SUDAMERIS | AH11: BBVA COLOMBIA | AI11: OCCIDENTE | AJ11: BANCO CAJA SOCIAL | AK11: DAVIVIENDA | AL11: SCOTIABANK COLPATRIA S.A | AM11: BANAGRARIO | AN11: BANCO AV VILLAS | AO11: BANCO CREDIFINANCIERA | AP11: BANCAMIA | AQ11: BANCO W S.A. | AR11: BANCOOMEVA | AS11: BANCO FINANDINA | AT11: BANCO FALABELLA S.A. | AU11: BANCO PICHINCHA S.A. | AV11: COOPCENTRAL | AW11: BANCO SANTANDER DE NEGOCIOS COLOMBIA | AX11: BANCO MUNDO MUJER S.A. | AY11: MIBANCO S.A. | AZ11: BANCO SERFINANZA S.A. | BA11: BANCO J.P: MORGAN COLOMBIA S.A. | BB11: LULO BANK S.A. | BC11: BANCO PTG PACTUAL | BD11: CORFICOLOMBIANA | BE11: B INV BANCOLOMBIA | BF11: BNP PARIBAS COLOMBIA | BG11: CORPORACIÓN FINANCIERA GNB SUDAMERIS S.A | BH11: CORPORACIÓN FINANCIERA DAVIVIENDA | BI11: GIROS Y FINANZAS | BJ11: COMPAÑÍA DE FINANCIAMIENTO TUYA | BK11: GM FINANCIAL COLOMBIA S.A. | BL11: COLTEFINANCIERA | BM11: DANN REGIONAL | BN11: CREDIFAMILIA | BO11: CREZCAMOS S.A. | BP11: LA HIPOTECARIA | BQ11: FINANCIERA JURISCOOP S.A. | BR11: RCI COLOMBIA S.A. | BS11: BANCAR TECNOLOGIA CO S.A. | BT11: COOP FINAN DE ANTIOQUIA | BU11: JFK COOPERATIVA FINANCIERA | BV11: COOP FINAN COOFINEP | BW11: COOP FINAN COTRAFA | BX11: COOP FINAN CONFIAR
C12: Cifras con corte a 24-feb-2022 | D12: dic-21 | E12: dic-21 | F12: dic-21 | G12: dic-21 | H12: dic-21 | I12: dic-21 | J12: dic-21 | K12: dic-21 | L12: dic-21 | M12: dic-21 | N12: dic-21 | O12: dic-21 | P12: dic-21 | Q12: dic-21 | R12: dic-21 | S12: dic-21 | T12: dic-21 | U12: dic-21 | V12: dic-21 | W12: dic-21 | X12: dic-21 | Y12: dic-21 | Z12: dic-21 | AA12: dic-21 | AB12: dic-21 | AC12: dic-21 | AD12: dic-21 | AE12: dic-21 | AF12: dic-21 | AG12: dic-21 | AH12: dic-21 | AI12: dic-21 | AJ12: dic-21 | AK12: dic-21 | AL12: dic-21 | AM12: dic-21 | AN12: dic-21 | AO12: dic-21 | AP12: dic-21 | AQ12: dic-21 | AR12: dic-21 | AS12: dic-21 | AT12: dic-21 | AU12: dic-21 | AV12: dic-21 | AW12: dic-21 | AX12: dic-21 | AY12: dic-21 | AZ12: dic-21 | BA12: dic-21 | BB12: dic-21 | BC12: dic-21 | BD12: dic-21 | BE12: dic-21 | BF12: dic-21 | BG12: dic-21 | BH12: dic-21 | BI12: dic-21 | BJ12: dic-21 | BK12: dic-21 | BL12: dic-21 | BM12: dic-21 | BN12: dic-21 | BO12: dic-21 | BP12: dic-21 | BQ12: dic-21 | BR12: dic-21 | BS12: dic-21 | BT12: dic-21 | BU12: dic-21 | BV12: dic-21 | BW12: dic-21 | BX12: dic-21
A13: BALANCE (cifras en $ millones)
A14: ACTIVOS | D14: 8.6102156e+08 | E14: 8.2435572e+08 | F14: 6.0102194e+08 | G14: 2.2333378e+08 | H14: 32216897 | I14: 4448949.1 | J14: 8.1757085e+08 | K14: 7.8535395e+08 | L14: 5.6825555e+08 | M14: 2.170984e+08 | N14: 32216897 | O14: 6.0047244e+08 | P14: 25217277 | Q14: 25217277 | R14: 24719512 | S14: 497764.6 | T14: 13784490 | U14: 8046878.3 | V14: 5737611.8 | W14: 13784490 | X14: 13784490 | Y14: 8046878.3 | Z14: 5737611.8 | AA14: 4448949.1 | AB14: 1.0863049e+08 | AC14: 29708064 | AD14: 30417280 | AE14: 2.0896007e+08 | AF14: 12366001 | AG14: 35958041 | AH14: 79516659 | AI14: 47147802 | AJ14: 18069652 | AK14: 1.1733175e+08 | AL14: 40258759 | AM14: 32216897 | AN14: 17253831 | AO14: 2050719.5 | AP14: 2056792.6 | AQ14: 2179116.2 | AR14: 4814725.7 | AS14: 2735091.4 | AT14: 6351326.6 | AU14: 3158147.4 | AV14: 1144241.7 | AW14: 5507740.6 | AX14: 2319961.9 | AY14: 1401990 | AZ14: 2294876.3 | BA14: 3462364.7 | BB14: 156363.69 | BC14: 102086.7 | BD14: 21712809 | BE14: 2019367.6 | BF14: 497764.6 | BG14: 754207.35 | BH14: 233128.86 | BI14: 905633.3 | BJ14: 3861357.3 | BK14: 2067923.3 | BL14: 895679.38 | BM14: 522454.61 | BN14: 573600.63 | BO14: 442584.47 | BP14: 357395.62 | BQ14: 1288153.2 | BR14: 2841496.8 | BS14: 28211.61 | BT14: 525872.89 | BU14: 1284334.3 | BV14: 319207.78 | BW14: 1055168.9 | BX14: 1264365.3
B15: DISPONIBLE | D15: 67795668 | E15: 65781171 | F15: 41275624 | G15: 24505546 | H15: 1471059.9 | I15: 543437.88 | J15: 63663067 | K15: 62192007 | L15: 37973359 | M15: 24218649 | N15: 1471059.9 | O15: 39444419 | P15: 2469564.6 | Q15: 2469564.6 | R15: 2464526.1 | S15: 5038.43 | T15: 1119598.5 | U15: 837739.57 | V15: 281858.98 | W15: 1119598.5 | X15: 1119598.5 | Y15: 837739.57 | Z15: 281858.98 | AA15: 543437.88 | AB15: 7322021.6 | AC15: 1682835.1 | AD15: 2427296.4 | AE15: 13333358 | AF15: 2799716.9 | AG15: 3622542.1 | AH15: 10268052 | AI15: 4408326.4 | AJ15: 1211127.7 | AK15: 7094112.2 | AL15: 3701888.9 | AM15: 1471059.9 | AN15: 884368.25 | AO15: 293924.81 | AP15: 144289.94 | AQ15: 330372.13 | AR15: 288537.91 | AS15: 202647.32 | AT15: 219602.39 | AU15: 210203.76 | AV15: 136865.98 | AW15: 866829.57 | AX15: 160577.59 | AY15: 183760.04 | AZ15: 261883.57 | BA15: 16620.89 | BB15: 34350.08 | BC15: 85896.16 | BD15: 1602383.8 | BE15: 822523.29 | BF15: 5038.43 | BG15: 11531.22 | BH15: 28087.85 | BI15: 109392.65 | BJ15: 353348.13 | BK15: 119794.46 | BL15: 113214.59 | BM15: 60410.57 | BN15: 36915.33 | BO15: 15426.42 | BP15: 38742.68 | BQ15: 164458.3 | BR15: 94098.13 | BS15: 13797.29 | BT15: 68623.83 | BU15: 173039.77 | BV15: 40973.92 | BW15: 126905.61 | BX15: 133894.75
B16: POSICIONES ACTIVAS EN OPERACIONES DE MERCADO MONETARIO Y RELACIONADAS | D16: 22515567 | E16: 22447883 | F16: 6856334.6 | G16: 15591549 | H16: 67683.73 | I16: 0 | J16: 21552983 | K16: 21485299 | L16: 5893750 | M16: 15591549 | N16: 67683.73 | O16: 5961433.8 | P16: 949386.47 | Q16: 949386.47 | R16: 949386.47 | S16: 0 | T16: 13198.12 | U16: 13198.12 | V16: 0 | W16: 13198.12 | X16: 13198.12 | Y16: 13198.12 | Z16: 0 | AA16: 0 | AB16: 69920.02 | AC16: 147007.26 | AD16: 2411319.2 | AE16: 1419807.7 | AF16: 1159172.8 | AG16: 8849894.3 | AH16: 737063.89 | AI16: 398024.52 | AJ16: 1350354.7 | AK16: 2220163.5 | AL16: 1286076.7 | AM16: 67683.73 | AN16: 24933.59 | AO16: 0 | AP16: 46006.46 | AQ16: 76874.63 | AR16: 14656.69 | AS16: 0 | AT16: 99500 | AU16: 0 | AV16: 0 | AW16: 230954.94 | AX16: 0 | AY16: 3000.49 | AZ16: 120000 | BA16: 817567.02 | BB16: 3000.49 | BC16: 0 | BD16: 949386.47 | BE16: 0 | BF16: 0 | BG16: 0 | BH16: 0 | BI16: 0 | BJ16: 0 | BK16: 0 | BL16: 0 | BM16: 0 | BN16: 0 | BO16: 0 | BP16: 0 | BQ16: 13198.12 | BR16: 0 | BS16: 0 | BT16: 0 | BU16: 0 | BV16: 0 | BW16: 0 | BX16: 0
C17: INTERBANCARIOS | D17: 4678851.2 | E17: 4611167.5 | F17: 3387897.7 | G17: 1223269.9 | H17: 67683.73 | I17: 0 | J17: 4371876 | K17: 4304192.3 | L17: 3080922.4 | M17: 1223269.9 | N17: 67683.73 | O17: 3148606.1 | P17: 306975.24 | Q17: 306975.24 | R17: 306975.24 | S17: 0 | T17: 0 | U17: 0 | V17: 0 | W17: 0 | X17: 0 | Y17: 0 | Z17: 0 | AA17: 0 | AB17: 40013.55 | AC17: 8201.19 | AD17: 384721.61 | AE17: 707904.43 | AF17: 0 | AG17: 115843.37 | AH17: 30009.72 | AI17: 325437.84 | AJ17: 1350354.7 | AK17: 477003.3 | AL17: 593195.15 | AM17: 67683.73 | AN17: 0 | AO17: 0 | AP17: 46006.46 | AQ17: 0 | AR17: 0 | AS17: 0 | AT17: 99500 | AU17: 0 | AV17: 0 | AW17: 0 | AX17: 0 | AY17: 3000.49 | AZ17: 120000 | BA17: 0 | BB17: 3000.49 | BC17: 0 | BD17: 306975.24 | BE17: 0 | BF17: 0 | BG17: 0 | BH17: 0 | BI17: 0 | BJ17: 0 | BK17: 0 | BL17: 0 | BM17: 0 | BN17: 0 | BO17: 0 | BP17: 0 | BQ17: 0 | BR17: 0 | BS17: 0 | BT17: 0 | BU17: 0 | BV17: 0 | BW17: 0 | BX17: 0
C18: OPERACIONES DE REPORTO O REPO | D18: 0 | E18: 0 | F18: 0 | G18: 0 | H18: 0 | I18: 0 | J18: 0 | K18: 0 | L18: 0 | M18: 0 | N18: 0 | O18: 0 | P18: 0 | Q18: 0 | R18: 0 | S18: 0 | T18: 0 | U18: 0 | V18: 0 | W18: 0 | X18: 0 | Y18: 0 | Z18: 0 | AA18: 0 | AB18: 0 | AC18: 0 | AD18: 0 | AE18: 0 | AF18: 0 | AG18: 0 | AH18: 0 | AI18: 0 | AJ18: 0 | AK18: 0 | AL18: 0 | AM18: 0 | AN18: 0 | AO18: 0 | AP18: 0 | AQ18: 0 | AR18: 0 | AS18: 0 | AT18: 0 | AU18: 0 | AV18: 0 | AW18: 0 | AX18: 0 | AY18: 0 | AZ18: 0 | BA18: 0 | BB18: 0 | BC18: 0 | BD18: 0 | BE18: 0 | BF18: 0 | BG18: 0 | BH18: 0 | BI18: 0 | BJ18: 0 | BK18: 0 | BL18: 0 | BM18: 0 | BN18: 0 | BO18: 0 | BP18: 0 | BQ18: 0 | BR18: 0 | BS18: 0 | BT18: 0 | BU18: 0 | BV18: 0 | BW18: 0 | BX18: 0
C19: OPERACIONES SIMULTÁNEAS | D19: 17836716 | E19: 17836716 | F19: 3468437 | G19: 14368279 | H19: 0 | I19: 0 | J19: 17181107 | K19: 17181107 | L19: 2812827.6 | M19: 14368279 | N19: 0 | O19: 2812827.6 | P19: 642411.23 | Q19: 642411.23 | R19: 642411.23 | S19: 0 | T19: 13198.12 | U19: 13198.12 | V19: 0 | W19: 13198.12 | X19: 13198.12 | Y19: 13198.12 | Z19: 0 | AA19: 0 | AB19: 29906.46 | AC19: 138806.07 | AD19: 2026597.6 | AE19: 711903.28 | AF19: 1159172.8 | AG19: 8734051 | AH19: 707054.17 | AI19: 72586.67 | AJ19: 0 | AK19: 1743160.2 | AL19: 692881.52 | AM19: 0 | AN19: 24933.59 | AO19: 0 | AP19: 0 | AQ19: 76874.63 | AR19: 14656.69 | AS19: 0 | AT19: 0 | AU19: 0 | AV19: 0 | AW19: 230954.94 | AX19: 0 | AY19: 0 | AZ19: 0 | BA19: 817567.02 | BB19: 0 | BC19: 0 | BD19: 642411.23 | BE19: 0 | BF19: 0 | BG19: 0 | BH19: 0 | BI19: 0 | BJ19: 0 | BK19: 0 | BL19: 0 | BM19: 0 | BN19: 0 | BO19: 0 | BP19: 0 | BQ19: 13198.12 | BR19: 0 | BS19: 0 | BT19: 0 | BU19: 0 | BV19: 0 | BW19: 0 | BX19: 0
C20: OPERACIONES DE TRANSFERENCIA TEMPORAL DE VALORES | D20: 0 | E20: 0 | F20: 0 | G20: 0 | H20: 0 | I20: 0 | J20: 0 | K20: 0 | L20: 0 | M20: 0 | N20: 0 | O20: 0 | P20: 0 | Q20: 0 | R20: 0 | S20: 0 | T20: 0 | U20: 0 | V20: 0 | W20: 0 | X20: 0 | Y20: 0 | Z20: 0 | AA20: 0 | AB20: 0 | AC20: 0 | AD20: 0 | AE20: 0 | AF20: 0 | AG20: 0 | AH20: 0 | AI20: 0 | AJ20: 0 | AK20: 0 | AL20: 0 | AM20: 0 | AN20: 0 | AO20: 0 | AP20: 0 | AQ20: 0 | AR20: 0 | AS20: 0 | AT20: 0 | AU20: 0 | AV20: 0 | AW20: 0 | AX20: 0 | AY20: 0 | AZ20: 0 | BA20: 0 | BB20: 0 | BC20: 0 | BD20: 0 | BE20: 0 | BF20: 0 | BG20: 0 | BH20: 0 | BI20: 0 | BJ20: 0 | BK20: 0 | BL20: 0 | BM20: 0 | BN20: 0 | BO20: 0 | BP20: 0 | BQ20: 0 | BR20: 0 | BS20: 0 | BT20: 0 | BU20: 0 | BV20: 0 | BW20: 0 | BX20: 0
C21: OTRAS POSICIONES ACTIVAS EN OPERACIONES DE MERCADO MONETARIO | D21: 0.0099999979 | E21: 0.0099999979 | F21: 0.02 | G21: -0.0099999998 | H21: 0 | I21: 0 | J21: 0.0099999979 | K21: 0.010000002 | L21: 0.02 | M21: -0.0099999998 | N21: 0 | O21: 0.02 | P21: 0 | Q21: 0 | R21: 0 | S21: 0 | T21: 0 | U21: 0 | V21: 0 | W21: 0 | X21: 0 | Y21: 0 | Z21: 0 | AA21: 0 | AB21: 0.01 | AC21: 0 | AD21: -0.01 | AE21: 0 | AF21: 0 | AG21: 0 | AH21: 0 | AI21: 0.01 | AJ21: 0 | AK21: 0 | AL21: 0 | AM21: 0 | AN21: 0 | AO21: 0 | AP21: 0 | AQ21: 0 | AR21: 0 | AS21: 0 | AT21: 0 | AU21: 0 | AV21: 0 | AW21: 0 | AX21: 0 | AY21: 0 | AZ21: 0 | BA21: 0 | BB21: 0 | BC21: 0 | BD21: 0 | BE21: 0 | BF21: 0 | BG21: 0 | BH21: 0 | BI21: 0 | BJ21: 0 | BK21: 0 | BL21: 0 | BM21: 0 | BN21: 0 | BO21: 0 | BP21: 0 | BQ21: 0 | BR21: 0 | BS21: 0 | BT21: 0 | BU21: 0 | BV21: 0 | BW21: 0 | BX21: 0
B22: INVERSIONES Y OPERACIONES CON DERIVADOS | D22: 1.9367992e+08 | E22: 1.7790376e+08 | F22: 1.3569436e+08 | G22: 42209405 | H22: 15419465 | I22: 356684.87 | J22: 1.7148951e+08 | K22: 1.5607004e+08 | L22: 1.1436017e+08 | M22: 41709877 | N22: 15419465 | O22: 1.2977963e+08 | P22: 21223296 | Q22: 21223296 | R22: 20801488 | S22: 421807.57 | T22: 610425.36 | U22: 532705.3 | V22: 77720.06 | W22: 610425.36 | X22: 610425.36 | Y22: 532705.3 | Z22: 77720.06 | AA22: 356684.87 | AB22: 34074776 | AC22: 5295881.2 | AD22: 4171100.9 | AE22: 44149292 | AF22: 5546201.6 | AG22: 11736059 | AH22: 10830911 | AI22: 8163289 | AJ22: 2512551.6 | AK22: 15764447 | AL22: 4491961.5 | AM22: 15419465 | AN22: 3197226.4 | AO22: 65568.64 | AP22: 33143.52 | AQ22: 61804.83 | AR22: 553230.9 | AS22: 69309.73 | AT22: 808932.34 | AU22: 543132.7 | AV22: 134399.31 | AW22: 1018342.2 | AX22: 132704.05 | AY22: 38948.1 | AZ22: 108016 | BA22: 2563235.5 | BB22: 5577.73 | BC22: 0 | BD22: 18761398 | BE22: 1188726.3 | BF22: 421807.57 | BG22: 712546.28 | BH22: 138817.84 | BI22: 215062.63 | BJ22: 109569.5 | BK22: 32837.75 | BL22: 71141.24 | BM22: 11917.47 | BN22: 3448.28 | BO22: 7354.91 | BP22: 18046.81 | BQ22: 121566.18 | BR22: 9469.49 | BS22: 10011.1 | BT22: 31035.35 | BU22: 102978 | BV22: 11340.64 | BW22: 124172.67 | BX22: 87158.21
C23: INVERSIONES A VALOR RAZONABLE CON CAMBIOS EN RESULTADOS - INSTRUMENTOS REPRESENTATIVOS DE DEUDA | D23: 26671359 | E23: 22755402 | F23: 16701036 | G23: 6054366 | H23: 3865857.6 | I23: 50098.96 | J23: 26267678 | K23: 22401821 | L23: 16519935 | M23: 5881885.2 | N23: 3865857.6 | O23: 20385793 | P23: 252233.74 | Q23: 252233.74 | R23: 93167.44 | S23: 159066.3 | T23: 101347.62 | U23: 87933.08 | V23: 13414.54 | W23: 101347.62 | X23: 101347.62 | Y23: 87933.08 | Z23: 13414.54 | AA23: 50098.96 | AB23: 940898.05 | AC23: 154777.83 | AD23: 754336.61 | AE23: 10983892 | AF23: 843186.84 | AG23: 4126.97 | AH23: 2554423.5 | AI23: 361289.09 | AJ23: 107371.2 | AK23: 3298599.7 | AL23: 570682.2 | AM23: 3865857.6 | AN23: 126849.71 | AO23: 14809.02 | AP23: 33142.49 | AQ23: 24178.74 | AR23: 306279.73 | AS23: 22460.12 | AT23: 45477.19 | AU23: 65564.86 | AV23: 74539.48 | AW23: 36451.27 | AX23: 68674.11 | AY23: 2173.69 | AZ23: 0 | BA23: 1007635.7 | BB23: 0 | BC23: 0 | BD23: 93167.44 | BE23: 0 | BF23: 159066.3 | BG23: 0 | BH23: 0 | BI23: 21220 | BJ23: 0 | BK23: 0 | BL23: 0 | BM23: 0 | BN23: 0 | BO23: 0 | BP23: 5006.68 | BQ23: 66713.08 | BR23: 0 | BS23: 8407.86 | BT23: 0 | BU23: 0 | BV23: 0 | BW23: 46587.31 | BX23: 3511.65
C24: INVERSIONES A VALOR RAZONABLE CON CAMBIOS EN RESULTADOS - INSTRUMENTOS DE PATRIMONIO | D24: 2026701.5 | E24: 2004376.2 | F24: 1450881.3 | G24: 553494.86 | H24: 0 | I24: 22325.33 | J24: 1864453 | K24: 1864453 | L24: 1320773.2 | M24: 543679.83 | N24: 0 | O24: 1320773.2 | P24: 119861.4 | Q24: 119861.4 | R24: 119861.4 | S24: 0 | T24: 20061.81 | U24: 10246.78 | V24: 9815.03 | W24: 20061.81 | X24: 20061.81 | Y24: 10246.78 | Z24: 9815.03 | AA24: 22325.33 | AB24: 624754.41 | AC24: 104167.89 | AD24: 9450.11 | AE24: 0 | AF24: 0 | AG24: 525724.5 | AH24: 0 | AI24: 422034.48 | AJ24: 218.94 | AK24: 11545.98 | AL24: 0 | AM24: 0 | AN24: 121738.68 | AO24: 3697.31 | AP24: 1.03 | AQ24: 803.2 | AR24: 0 | AS24: 150.05 | AT24: 0 | AU24: 8505.22 | AV24: 1058.01 | AW24: 0 | AX24: 28269.49 | AY24: 812.7 | AZ24: 1520.99 | BA24: 0 | BB24: 0 | BC24: 0 | BD24: 114736.4 | BE24: 5125 | BF24: 0 | BG24: 0 | BH24: 0 | BI24: 0 | BJ24: 7438.78 | BK24: 361.01 | BL24: 0 | BM24: 0 | BN24: 635.83 | BO24: 3643.74 | BP24: 936.33 | BQ24: 2172.17 | BR24: 3270.71 | BS24: 1603.24 | BT24: 10798.4 | BU24: 0 | BV24: 86.14 | BW24: 420.12 | BX24: 11020.67
C25: INVERSIONES A COSTO AMORTIZADO | D25: 26968300 | E25: 16909191 | F25: 13647225 | G25: 3261966.8 | H25: 9792908.2 | I25: 266200.91 | J25: 26441440 | K25: 16648532 | L25: 13431117 | M25: 3217415 | N25: 9792908.2 | O25: 23224025 | P25: 126.01 | Q25: 126.01 | R25: 126.01 | S25: 0 | T25: 260533.21 | U25: 215981.37 | V25: 44551.84 | W25: 260533.21 | X25: 260533.21 | Y25: 215981.37 | Z25: 44551.84 | AA25: 266200.91 | AB25: 2726597.2 | AC25: 1095453.9 | AD25: 682233.41 | AE25: 3120957.4 | AF25: 0 | AG25: 1185867.3 | AH25: 55422.37 | AI25: 775923.02 | AJ25: 1334860.1 | AK25: 3403052.1 | AL25: 773935.57 | AM25: 9792908.2 | AN25: 483919.05 | AO25: 44889.98 | AP25: 0 | AQ25: 29886.93 | AR25: 158564.48 | AS25: 23463.81 | AT25: 314232.9 | AU25: 43325.37 | AV25: 55494.21 | AW25: 162398.03 | AX25: 35760.45 | AY25: 35798.95 | AZ25: 106495.01 | BA25: 0 | BB25: 0.48 | BC25: 0 | BD25: 0 | BE25: 126.01 | BF25: 0 | BG25: 0 | BH25: 0 | BI25: 17499.44 | BJ25: 102130.72 | BK25: 32476.74 | BL25: 29830.91 | BM25: 11911.55 | BN25: 2812.45 | BO25: 3711.17 | BP25: 2165.15 | BQ25: 51796.3 | BR25: 6198.78 | BS25: 0 | BT25: 16394.97 | BU25: 102978 | BV25: 10897.04 | BW25: 65385.65 | BX25: 70545.25
C26: INVERSIONES A VALOR RAZONABLE CON CAMBIOS EN EL ORI - INSTRUMENTOS DE PATRIMONIO | D26: 3441351.1 | E26: 3271277 | F26: 2818316.4 | G26: 452960.63 | H26: 164663.7 | I26: 5410.38 | J26: 2049560.5 | K26: 1884896.8 | L26: 1431936.2 | M26: 452960.63 | N26: 164663.7 | O26: 1596599.9 | P26: 1368038.2 | Q26: 1368038.2 | R26: 1368038.2 | S26: 0 | T26: 18342.05 | U26: 18342.05 | V26: 0 | W26: 18342.05 | X26: 18342.05 | Y26: 18342.05 | Z26: 0 | AA26: 5410.38 | AB26: 271578.68 | AC26: 150617.44 | AD26: 34323.78 | AE26: 172424.16 | AF26: 74935.16 | AG26: 0 | AH26: 282266.5 | AI26: 110822.4 | AJ26: 136929.48 | AK26: 477538.75 | AL26: 61272.43 | AM26: 164663.7 | AN26: 96553.02 | AO26: 2172.33 | AP26: 0 | AQ26: 0 | AR26: 11788.24 | AS26: 1348.89 | AT26: 0 | AU26: 162.76 | AV26: 0 | AW26: 0 | AX26: 0 | AY26: 162.76 | AZ26: 0 | BA26: 0 | BB26: 0 | BC26: 0 | BD26: 1335870.5 | BE26: 32167.74 | BF26: 0 | BG26: 0 | BH26: 0 | BI26: 0 | BJ26: 0 | BK26: 0 | BL26: 17147.22 | BM26: 0 | BN26: 0 | BO26: 0 | BP26: 0 | BQ26: 1194.83 | BR26: 0 | BS26: 0 | BT26: 765.73 | BU26: 0 | BV26: 357.46 | BW26: 1556.37 | BX26: 2730.82
C27: INVERSIONES A VALOR RAZONABLE CON CAMBIOS EN RESULTADOS ENTREGADOS EN OPERACIONES DE MERCADO MONETARIO - INSTRUMENTOS REPRESENTATIVOS DE DEUDA (DERECHOS DE TRANSFERENCIA) | D27: 6903788.4 | E27: 5522002.6 | F27: 2690455.8 | G27: 2831546.8 | H27: 1381785.9 | I27: 0 | J27: 4956874 | K27: 3575088.1 | L27: 858356.32 | M27: 2716731.8 | N27: 1381785.9 | O27: 2240142.2 | P27: 1946914.5 | Q27: 1946914.5 | R27: 1832099.5 | S27: 114815.03 | T27: 0 | U27: 0 | V27: 0 | W27: 0 | X27: 0 | Y27: 0 | Z27: 0 | AA27: 0 | AB27: 0 | AC27: 0 | AD27: 38030.67 | AE27: 420792.3 | AF27: 624025.12 | AG27: 0 | AH27: 169048.78 | AI27: 329126.17 | AJ27: 0 | AK27: 94566.03 | AL27: 569797.32 | AM27: 1381785.9 | AN27: 0 | AO27: 0 | AP27: 0 | AQ27: 0 | AR27: 13871.82 | AS27: 0 | AT27: 0 | AU27: 0 | AV27: 0 | AW27: 0 | AX27: 0 | AY27: 0 | AZ27: 0 | BA27: 1315829.9 | BB27: 0 | BC27: 0 | BD27: 1832099.5 | BE27: 0 | BF27: 114815.03 | BG27: 0 | BH27: 0 | BI27: 0 | BJ27: 0 | BK27: 0 | BL27: 0 | BM27: 0 | BN27: 0 | BO27: 0 | BP27: 0 | BQ27: 0 | BR27: 0 | BS27: 0 | BT27: 0 | BU27: 0 | BV27: 0 | BW27: 0 | BX27: 0
C28: INVERSIONES A VALOR RAZONABLE CON CAMBIOS EN RESULTADOS ENTREGADOS EN OPERACIONES DE MERCADO MONETARIO - INSTRUMENTOS DE PATRIMONIO (DERECHOS DE TRANSFERENCIA) | D28: 0 | E28: 0 | F28: 0 | G28: 0 | H28: 0 | I28: 0 | J28: 0 | K28: 0 | L28: 0 | M28: 0 | N28: 0 | O28: 0 | P28: 0 | Q28: 0 | R28: 0 | S28: 0 | T28: 0 | U28: 0 | V28: 0 | W28: 0 | X28: 0 | Y28: 0 | Z28: 0 | AA28: 0 | AB28: 0 | AC28: 0 | AD28: 0 | AE28: 0 | AF28: 0 | AG28: 0 | AH28: 0 | AI28: 0 | AJ28: 0 | AK28: 0 | AL28: 0 | AM28: 0 | AN28: 0 | AO28: 0 | AP28: 0 | AQ28: 0 | AR28: 0 | AS28: 0 | AT28: 0 | AU28: 0 | AV28: 0 | AW28: 0 | AX28: 0 | AY28: 0 | AZ28: 0 | BA28: 0 | BB28: 0 | BC28: 0 | BD28: 0 | BE28: 0 | BF28: 0 | BG28: 0 | BH28: 0 | BI28: 0 | BJ28: 0 | BK28: 0 | BL28: 0 | BM28: 0 | BN28: 0 | BO28: 0 | BP28: 0 | BQ28: 0 | BR28: 0 | BS28: 0 | BT28: 0 | BU28: 0 | BV28: 0 | BW28: 0 | BX28: 0
C29: INVERSIONES A COSTO AMORTIZADO CON CAMBIOS EN RESULTADOS ENTREGADOS EN OPERACIONES DE MERCADO MONETARIO - INSTRUMENTOS REPRESENTATIVOS DE DEUDA (DERECHOS DE TRANSFERENCIA) | D29: 2429124.3 | E29: 2429124.3 | F29: 398452.95 | G29: 2030671.3 | H29: 0 | I29: 0 | J29: 2353895.9 | K29: 2353895.9 | L29: 323224.55 | M29: 2030671.3 | N29: 0 | O29: 323224.55 | P29: 75228.4 | Q29: 75228.4 | R29: 75228.4 | S29: 0 | T29: 0 | U29: 0 | V29: 0 | W29: 0 | X29: 0 | Y29: 0 | Z29: 0 | AA29: 0 | AB29: 100000 | AC29: 0 | AD29: 0 | AE29: 0 | AF29: 0 | AG29: 0 | AH29: 2030671.3 | AI29: 126690.73 | AJ29: 50981.14 | AK29: 0 | AL29: 0 | AM29: 0 | AN29: 0 | AO29: 0 | AP29: 0 | AQ29: 0 | AR29: 45552.68 | AS29: 0 | AT29: 0 | AU29: 0 | AV29: 0 | AW29: 0 | AX29: 0 | AY29: 0 | AZ29: 0 | BA29: 0 | BB29: 0 | BC29: 0 | BD29: 75228.4 | BE29: 0 | BF29: 0 | BG29: 0 | BH29: 0 | BI29: 0 | BJ29: 0 | BK29: 0 | BL29: 0 | BM29: 0 | BN29: 0 | BO29: 0 | BP29: 0 | BQ29: 0 | BR29: 0 | BS29: 0 | BT29: 0 | BU29: 0 | BV29: 0 | BW29: 0 | BX29: 0
C30: INVERSIONES A VALOR RAZONABLE CON CAMBIOS EN EL ORI ENTREGADOS EN OPERACIONES DE MERCADO MONETARIO - INSTRUMENTOS DE PATRIMONIO | D30: 0 | E30: 0 | F30: 0 | G30: 0 | H30: 0 | I30: 0 | J30: 0 | K30: 0 | L30: 0 | M30: 0 | N30: 0 | O30: 0 | P30: 0 | Q30: 0 | R30: 0 | S30: 0 | T30: 0 | U30: 0 | V30: 0 | W30: 0 | X30: 0 | Y30: 0 | Z30: 0 | AA30: 0 | AB30: 0 | AC30: 0 | AD30: 0 | AE30: 0 | AF30: 0 | AG30: 0 | AH30: 0 | AI30: 0 | AJ30: 0 | AK30: 0 | AL30: 0 | AM30: 0 | AN30: 0 | AO30: 0 | AP30: 0 | AQ30: 0 | AR30: 0 | AS30: 0 | AT30: 0 | AU30: 0 | AV30: 0 | AW30: 0 | AX30: 0 | AY30: 0 | AZ30: 0 | BA30: 0 | BB30: 0 | BC30: 0 | BD30: 0 | BE30: 0 | BF30: 0 | BG30: 0 | BH30: 0 | BI30: 0 | BJ30: 0 | BK30: 0 | BL30: 0 | BM30: 0 | BN30: 0 | BO30: 0 | BP30: 0 | BQ30: 0 | BR30: 0 | BS30: 0 | BT30: 0 | BU30: 0 | BV30: 0 | BW30: 0 | BX30: 0
C31: INVERSIONES A VALOR RAZONABLE CON CAMBIOS EN RESULTADOS ENTREGADAS EN GARANTÍA DE OPERACIONES CON INSTRUMENTOS DERIVADOS - INSTRUMENTOS REPRESENTATIVOS DE DEUDA | D31: 930369.98 | E31: 821161.2 | F31: 548116.39 | G31: 273044.81 | H31: 109208.78 | I31: 0 | J31: 925794.53 | K31: 816585.75 | L31: 543540.94 | M31: 273044.81 | N31: 109208.78 | O31: 652749.72 | P31: 4575.45 | Q31: 4575.45 | R31: 4575.45 | S31: 0 | T31: 0 | U31: 0 | V31: 0 | W31: 0 | X31: 0 | Y31: 0 | Z31: 0 | AA31: 0 | AB31: 0 | AC31: 0 | AD31: 5322.6 | AE31: 543540.94 | AF31: 11154.5 | AG31: 0 | AH31: 0 | AI31: 0 | AJ31: 0 | AK31: 0 | AL31: 55491.82 | AM31: 109208.78 | AN31: 0 | AO31: 0 | AP31: 0 | AQ31: 0 | AR31: 0 | AS31: 0 | AT31: 0 | AU31: 0 | AV31: 0 | AW31: 0 | AX31: 0 | AY31: 0 | AZ31: 0 | BA31: 201075.89 | BB31: 0 | BC31: 0 | BD31: 4575.45 | BE31: 0 | BF31: 0 | BG31: 0 | BH31: 0 | BI31: 0 | BJ31: 0 | BK31: 0 | BL31: 0 | BM31: 0 | BN31: 0 | BO31: 0 | BP31: 0 | BQ31: 0 | BR31: 0 | BS31: 0 | BT31: 0 | BU31: 0 | BV31: 0 | BW31: 0 | BX31: 0
C32: INVERSIONES A VALOR RAZONABLE CON CAMBIOS EN RESULTADOS ENTREGADOS EN GARANTÍA DE OPERACIONES CON INSTRUMENTOS DERIVADOS - INSTRUMENTOS DE PATRIMONIO | D32: 0 | E32: 0 | F32: 0 | G32: 0 | H32: 0 | I32: 0 | J32: 0 | K32: 0 | L32: 0 | M32: 0 | N32: 0 | O32: 0 | P32: 0 | Q32: 0 | R32: 0 | S32: 0 | T32: 0 | U32: 0 | V32: 0 | W32: 0 | X32: 0 | Y32: 0 | Z32: 0 | AA32: 0 | AB32: 0 | AC32: 0 | AD32: 0 | AE32: 0 | AF32: 0 | AG32: 0 | AH32: 0 | AI32: 0 | AJ32: 0 | AK32: 0 | AL32: 0 | AM32: 0 | AN32: 0 | AO32: 0 | AP32: 0 | AQ32: 0 | AR32: 0 | AS32: 0 | AT32: 0 | AU32: 0 | AV32: 0 | AW32: 0 | AX32: 0 | AY32: 0 | AZ32: 0 | BA32: 0 | BB32: 0 | BC32: 0 | BD32: 0 | BE32: 0 | BF32: 0 | BG32: 0 | BH32: 0 | BI32: 0 | BJ32: 0 | BK32: 0 | BL32: 0 | BM32: 0 | BN32: 0 | BO32: 0 | BP32: 0 | BQ32: 0 | BR32: 0 | BS32: 0 | BT32: 0 | BU32: 0 | BV32: 0 | BW32: 0 | BX32: 0
C33: INVERSIONES A COSTO AMORTIZADO CON CAMBIOS EN RESULTADOS ENTREGADOS EN GARANTÍA DE OPERACIONES CON INSTRUMENTOS DERIVADOS - INSTRUMENTOS REPRESENTATIVOS DE DEUDA | D33: 99872.16 | E33: 64317.65 | F33: 0 | G33: 64317.65 | H33: 35554.51 | I33: 0 | J33: 99872.16 | K33: 64317.65 | L33: 0 | M33: 64317.65 | N33: 35554.51 | O33: 35554.51 | P33: 0 | Q33: 0 | R33: 0 | S33: 0 | T33: 0 | U33: 0 | V33: 0 | W33: 0 | X33: 0 | Y33: 0 | Z33: 0 | AA33: 0 | AB33: 0 | AC33: 0 | AD33: 0 | AE33: 0 | AF33: 0 | AG33: 0 | AH33: 0 | AI33: 0 | AJ33: 0 | AK33: 0 | AL33: 0 | AM33: 35554.51 | AN33: 0 | AO33: 0 | AP33: 0 | AQ33: 0 | AR33: 0 | AS33: 0 | AT33: 0 | AU33: 0 | AV33: 0 | AW33: 64317.65 | AX33: 0 | AY33: 0 | AZ33: 0 | BA33: 0 | BB33: 0 | BC33: 0 | BD33: 0 | BE33: 0 | BF33: 0 | BG33: 0 | BH33: 0 | BI33: 0 | BJ33: 0 | BK33: 0 | BL33: 0 | BM33: 0 | BN33: 0 | BO33: 0 | BP33: 0 | BQ33: 0 | BR33: 0 | BS33: 0 | BT33: 0 | BU33: 0 | BV33: 0 | BW33: 0 | BX33: 0
C34: INVERSIONES A VALOR RAZONABLE CON CAMBIOS EN EL ORI ENTREGADOS EN GARANTÍA DE OPERACIONES CON INSTRUMENTOS DERIVADOS - INSTRUMENTOS DE PATRIMONIO | D34: 0 | E34: 0 | F34: 0 | G34: 0 | H34: 0 | I34: 0 | J34: 0 | K34: 0 | L34: 0 | M34: 0 | N34: 0 | O34: 0 | P34: 0 | Q34: 0 | R34: 0 | S34: 0 | T34: 0 | U34: 0 | V34: 0 | W34: 0 | X34: 0 | Y34: 0 | Z34: 0 | AA34: 0 | AB34: 0 | AC34: 0 | AD34: 0 | AE34: 0 | AF34: 0 | AG34: 0 | AH34: 0 | AI34: 0 | AJ34: 0 | AK34: 0 | AL34: 0 | AM34: 0 | AN34: 0 | AO34: 0 | AP34: 0 | AQ34: 0 | AR34: 0 | AS34: 0 | AT34: 0 | AU34: 0 | AV34: 0 | AW34: 0 | AX34: 0 | AY34: 0 | AZ34: 0 | BA34: 0 | BB34: 0 | BC34: 0 | BD34: 0 | BE34: 0 | BF34: 0 | BG34: 0 | BH34: 0 | BI34: 0 | BJ34: 0 | BK34: 0 | BL34: 0 | BM34: 0 | BN34: 0 | BO34: 0 | BP34: 0 | BQ34: 0 | BR34: 0 | BS34: 0 | BT34: 0 | BU34: 0 | BV34: 0 | BW34: 0 | BX34: 0
... C63: DETERIORO EN INVERSIONES A VALOR RAZONABLE | D63: 125824.87 | E63: 125608.44 | F63: 125608.44 | G63: 0 | H63: 0 | I63: 216.43 | J63: 24857.29 | K63: 24857.29 | L63: 24857.29 | M63: 0 | N63: 0 | O63: 24857.29 | P63: 100751.15 | Q63: 100751.15 | R63: 100751.15 | S63: 0 | T63: 0 | U63: 0 | V63: 0 | W63: 0 | X63: 0 | Y63: 0 | Z63: 0 | AA63: 216.43 | AB63: 23631.88 | AC63: 689.97 | AD63: 0 | AE63: 0 | AF63: 0 | AG63: 0 | AH63: 0 | AI63: 423.62 | AJ63: 0 | AK63: 0 | AL63: 0 | AM63: 0 | AN63: 0 | AO63: 0 | AP63: 0 | AQ63: 0 | AR63: 0 | AS63: 0 | AT63: 0 | AU63: 0 | AV63: 111.82 | AW63: 0 | AX63: 0 | AY63: 0 | AZ63: 0 | BA63: 0 | BB63: 0 | BC63: 0 | BD63: 100751.15 | BE63: 0 | BF63: 0 | BG63: 0 | BH63: 0 | BI63: 0 | BJ63: 0 | BK63: 0 | BL63: 0 | BM63: 0 | BN63: 0 | BO63: 0 | BP63: 0 | BQ63: 0 | BR63: 0 | BS63: 0 | BT63: 0 | BU63: 0 | BV63: 0 | BW63: 35 | BX63: 181.43
B64: CARTERA DE CREDITOS Y OPERACIONES DE LEASING | D64: 5.2881346e+08 | E64: 5.1132506e+08 | F64: 3.8078307e+08 | G64: 1.3054199e+08 | H64: 14175668 | I64: 3312734.2 | J64: 5.1458786e+08 | K64: 5.0041219e+08 | L64: 3.7480975e+08 | M64: 1.2560245e+08 | N64: 14175668 | O64: 3.8898541e+08 | P64: 0 | Q64: 0 | R64: 0 | S64: 0 | T64: 10912869 | U64: 5973327.4 | V64: 4939541.8 | W64: 10912869 | X64: 10912869 | Y64: 5973327.4 | Z64: 4939541.8 | AA64: 3312734.2 | AB64: 60344884 | AC64: 21340077 | AD64: 19809785 | AE64: 1.356714e+08 | AF64: 2686371.6 | AG64: 10515136 | AH64: 54191676 | AI64: 32044982 | AJ64: 11715250 | AK64: 85649331 | AL64: 28178938 | AM64: 14175668 | AN64: 12181127 | AO64: 1459202.7 | AP64: 1543544.6 | AQ64: 1342563.1 | AR64: 3758155.5 | AS64: 2400027.4 | AT64: 4801338.4 | AU64: 2201930.4 | AV64: 826290.59 | AW64: 3181224.8 | AX64: 1873241.4 | AY64: 985202.59 | AZ64: 1674448.5 | BA64: 36044.97 | BB64: 12.63 | BC64: 0 | BD64: 0 | BE64: 0 | BF64: 0 | BG64: 0 | BH64: 0 | BI64: 457792.69 | BJ64: 3105577.3 | BK64: 1751624.3 | BL64: 612233 | BM64: 362063.33 | BN64: 523585.29 | BO64: 356294.22 | BP64: 284933.61 | BQ64: 912075.78 | BR64: 2546689.6 | BS64: 0 | BT64: 376601.61 | BU64: 969029.11 | BV64: 247169.47 | BW64: 744072.5 | BX64: 975861.53
C65: CARTERA DE CREDITOS | D65: 5.6576322e+08 | E65: 5.4656803e+08 | F65: 4.0830002e+08 | G65: 1.3826801e+08 | H65: 15487799 | I65: 3707387.5 | J65: 5.5020427e+08 | K65: 5.3471648e+08 | L65: 4.0165232e+08 | M65: 1.3306416e+08 | N65: 15487799 | O65: 4.1714011e+08 | P65: 0 | Q65: 0 | R65: 0 | S65: 0 | T65: 11851555 | U65: 6647705.8 | V65: 5203849.5 | W65: 11851555 | X65: 11851555 | Y65: 6647705.8 | Z65: 5203849.5 | AA65: 3707387.5 | AB65: 64792731 | AC65: 22546234 | AD65: 21283364 | AE65: 1.4676048e+08 | AF65: 2720195.2 | AG65: 10947792 | AH65: 57632221 | AI65: 34208817 | AJ65: 12448223 | AK65: 90903256 | AL65: 29678746 | AM65: 15487799 | AN65: 12827816 | AO65: 1551733.9 | AP65: 1645477.7 | AQ65: 1511073.8 | AR65: 4024717.3 | AS65: 2632881.3 | AT65: 5122428.2 | AU65: 2379390 | AV65: 855119.78 | AW65: 3263524.1 | AX65: 2010134.6 | AY65: 1079277.4 | AZ65: 1854327.5 | BA65: 36500 | BB65: 13 | BC65: 0 | BD65: 0 | BE65: 0 | BF65: 0 | BG65: 0 | BH65: 0 | BI65: 500127.15 | BJ65: 3614824.8 | BK65: 1840505.9 | BL65: 637083.48 | BM65: 399620.16 | BN65: 539132.68 | BO65: 389279 | BP65: 296270.87 | BQ65: 956917.46 | BR65: 2677793.7 | BS65: 0 | BT65: 429056.65 | BU65: 1190075.3 | BV65: 262431.46 | BW65: 796149.98 | BX65: 1029674.1
C66: CARTERA Y OPERACIONES DE LEASING COMERCIALES | D66: 2.8608012e+08 | E66: 2.7815846e+08 | F66: 2.175754e+08 | G66: 60583064 | H66: 7342607.1 | I66: 579046.85 | J66: 2.8380355e+08 | K66: 2.7646094e+08 | L66: 2.1685043e+08 | M66: 59610515 | N66: 7342607.1 | O66: 2.2419303e+08 | P66: 0 | Q66: 0 | R66: 0 | S66: 0 | T66: 1697524.3 | U66: 724975.55 | V66: 972548.77 | W66: 1697524.3 | X66: 1697524.3 | Y66: 724975.55 | Z66: 972548.77 | AA66: 579046.85 | AB66: 44003638 | AC66: 6287127.7 | AD66: 13302764 | AE66: 95918912 | AF66: 2720195.2 | AG66: 5407122 | AH66: 22216442 | AI66: 23381461 | AJ66: 2133729.7 | AK66: 39313210 | AL66: 12670785 | AM66: 7342607.1 | AN66: 2716622.1 | AO66: 88858.63 | AP66: 122324.13 | AQ66: 149903.85 | AR66: 635726.75 | AS66: 260054.81 | AT66: 0 | AU66: 651451.68 | AV66: 733112.4 | AW66: 2605256.1 | AX66: 246432.21 | AY66: 234655.11 | AZ66: 624657.09 | BA66: 36500 | BB66: 0 | BC66: 0 | BD66: 0 | BE66: 0 | BF66: 0 | BG66: 0 | BH66: 0 | BI66: 21216.29 | BJ66: 0 | BK66: 552680.78 | BL66: 424797.75 | BM66: 202164.36 | BN66: 1974.92 | BO66: 64525.07 | BP66: 0 | BQ66: 74822.23 | BR66: 355342.92 | BS66: 0 | BT66: 144582.58 | BU66: 79753.5 | BV66: 65445.69 | BW66: 48884.6 | BX66: 240380.48
C67: CARTERA Y OPERACIONES DE LEASING DE CONSUMO | D67: 1.8086569e+08 | E67: 1.7735147e+08 | F67: 1.2335223e+08 | G67: 53999245 | H67: 1203868.6 | I67: 2310345 | J67: 1.6960284e+08 | K67: 1.6839897e+08 | L67: 1.180616e+08 | M67: 50337376 | N67: 1203868.6 | O67: 1.1926546e+08 | P67: 0 | Q67: 0 | R67: 0 | S67: 0 | T67: 8952502.9 | U67: 5290633.8 | V67: 3661869 | W67: 8952502.9 | X67: 8952502.9 | Y67: 5290633.8 | Z67: 3661869 | AA67: 2310345 | AB67: 14907105 | AC67: 15084895 | AD67: 4566209.4 | AE67: 33819776 | AF67: 0 | AG67: 5501893 | AH67: 21851433 | AI67: 8745518 | AJ67: 3191251.3 | AK67: 27395483 | AL67: 10909206 | AM67: 1203868.6 | AN67: 7617007.1 | AO67: 1330743.6 | AP67: 8206.64 | AQ67: 72461.96 | AR67: 1960332.6 | AS67: 2371888.2 | AT67: 5122428.2 | AU67: 1727938.4 | AV67: 110822.3 | AW67: 658268 | AX67: 208401.27 | AY67: 8020.17 | AZ67: 1229670.4 | BA67: 0 | BB67: 13 | BC67: 0 | BD67: 0 | BE67: 0 | BF67: 0 | BG67: 0 | BH67: 0 | BI67: 385872.15 | BJ67: 3614824.8 | BK67: 1287825.2 | BL67: 209271.63 | BM67: 197455.8 | BN67: 1114.2 | BO67: 241.36 | BP67: 51351.75 | BQ67: 882095.23 | BR67: 2322450.8 | BS67: 0 | BT67: 162741.22 | BU67: 1002615.7 | BV67: 162342.91 | BW67: 646687.16 | BX67: 335958.09
C68: CARTERA Y LEASING DE MICROCRÉDITOS | D68: 14552533 | E68: 7342627 | F68: 7018112.9 | G68: 324514.08 | H68: 6865179.8 | I68: 344725.81 | J68: 13883294 | K68: 7018114.4 | L68: 7018112.9 | M68: 1.51 | N68: 6865179.8 | O68: 13883293 | P68: 0 | Q68: 0 | R68: 0 | S68: 0 | T68: 324512.57 | U68: 0 | V68: 324512.57 | W68: 324512.57 | X68: 324512.57 | Y68: 0 | Z68: 324512.57 | AA68: 344725.81 | AB68: 272654.37 | AC68: 2792.73 | AD68: 0 | AE68: 635056.98 | AF68: 0 | AG68: 0 | AH68: 1.51 | AI68: 0 | AJ68: 827916.08 | AK68: 5041.23 | AL68: 0 | AM68: 6865179.8 | AN68: 212.18 | AO68: 132131.63 | AP68: 1498383.4 | AQ68: 1288708 | AR68: 0 | AS68: 28.79 | AT68: 0 | AU68: 0 | AV68: 11185.08 | AW68: 0 | AX68: 1555301.1 | AY68: 788701.35 | AZ68: 0 | BA68: 0 | BB68: 0 | BC68: 0 | BD68: 0 | BE68: 0 | BF68: 0 | BG68: 0 | BH68: 0 | BI68: 0 | BJ68: 0 | BK68: 0 | BL68: 0 | BM68: 0 | BN68: 0 | BO68: 324512.57 | BP68: 0 | BQ68: 0 | BR68: 0 | BS68: 0 | BT68: 109880.36 | BU68: 107599.47 | BV68: 2605.72 | BW68: 22900.95 | BX68: 101739.31
...

Sheet 2022
C1: Identificador | D1: +1+2+4+32+22-0-0-0-0-0-0-0-0 | E1: 0-+1-0-0-0-0-0-0-0 | F1: 0-+1-+1-0-0-0-0-0-0 | G1: 0-+1-+2-0-0-0-0-0-0 | H1: 0-+2-0-0-0-0-0-0-0 | I1: 32-3-0-0-0-0-0-0-0 | J1: 1-0-0-0-0-0-0-0-0 | K1: 1-1-0-0-0-0-0-0-0 | L1: 0-0-0-0-0-+200-0-0-0 | M1: +1-0-+2-0-0-0-0-0-0 | N1: 0-0-0-0-0-+100-0-0-0 | O1: 1-0-1-0-0-0-0-0-0 | P1: 2-0-0-0-0-0-0-0-0 | Q1: 2-1-0-0-0-0-0-0-0 | R1: 2-1-1-0-0-0-0-0-0 | S1: 2-1-2-0-0-0-0-0-0 | T1: +4-0-0-0-0-0-0-0-0 | U1: 4-0-1-0-0-0-0-0-0 | V1: 4-0-2-0-0-0-0-0-0 | W1: 4-0-0-1-0-0-0-0-0 | X1: 4-1-0-1-0-0-0-0-0 | Y1: 4-1-1-1-0-0-0-0-0 | Z1: 4-1-2-1-0-0-0-0-0 | AA1: +32-3-0-0-0-0-0-0-0 | AB1: 1-1-1-1-1-200-1-1- | AC1: 1-1-1-1-2-200-1-1- | AD1: 1-1-2-1-6-0-1-1- | AE1: 1-1-1-1-7-200-1-2- | AF1: 1-1-2-1-9-0-1-3- | AG1: 1-1-2-1-12-0-1-3- | AH1: 1-1-2-1-13-0-1-3- | AI1: 1-1-1-1-23-200-1-1- | AJ1: 1-1-1-2-30-200-7-3- | AK1: 1-1-1-2-39-200-7-2- | AL1: 1-1-2-2-42-0-7-3- | AM1: 1-2-1-1-43-100-1-2- | AN1: 1-1-1-2-49-200-7-1- | AO1: 1-1-1-1-51-200-6-3- | AP1: 1-1-1-1-52-200-6-3- | AQ1: 1-1-1-1-53-200-6-3- | AR1: 1-1-1-1-54-200-6-3- | AS1: 1-1-1-1-55-200-6-3- | AT1: 1-1-2-1-56-0-6-3- | AU1: 1-1-2-1-57-0-6-3- | AV1: 1-1-1-1-58-200-1-3- | AW1: 1-1-2-1-59-0-1-1- | AX1: 1-1-1-1-60-200-1-1- | AY1: 1-1-1-1-62-200-1-1- | AZ1: 1-1-1-1-63-200-1-1- | BA1: 1-1-2-1-64-0-1-1- | BB1: 1-1-1-1-65-200-1-1- | BC1: 1-1-2-1-66-0-1-1- | BD1: 1-1-1-1-67-200-1-1- | BE1: 2-1-1-4-11-0-1-1- | BF1: 2-1-1-4-37-0-1-2- | BG1: 2-1-2-4-42-0-2-0- | BH1: 2-1-1-4-48-0-2-0- | BI1: 2-1-1-4-49-0-2-0- | BJ1: 4-1-1-1-26-0-1-2- | BK1: 4-1-2-1-31-0-1-3- | BL1: 4-1-1-1-46-0-6-1- | BM1: 4-1-1-1-108-0-1-2- | BN1: 4-1-1-1-117-0-0-3- | BO1: 4-1-2-1-118-0-0-3- | BP1: 4-1-2-1-120-0-0-3- | BQ1: 4-1-1-1-121-0-0-3- | BR1: 4-1-2-1-122-0-0-3- | BS1: 4-1-2-1-123-0-0-3- | BT1: 4-1-2-1-125-0-0-3- | BU1: 32-3-1-1-1-0-1-1-300 | BV1: 32-3-1-1-2-0-1-3-300 | BW1: 32-3-1-1-3-0-1-2-300 | BX1: 32-3-1-1-4-0-1-2-300 | BY1: 32-3-1-1-5-0-1-3-300
C2: Tipo | D2: +1+2+4+32+22 | E2: 0 | F2: 0 | G2: 0 | H2: 0 | I2: 32 | J2: 1 | K2: 1 | L2: 0 | M2: +1 | N2: 0 | O2: 1 | P2: 2 | Q2: 2 | R2: 2 | S2: 2 | T2: +4 | U2: 4 | V2: 4 | W2: 4 | X2: 4 | Y2: 4 | Z2: 4 | AA2: +32 | AB2: 1 | AC2: 1 | AD2: 1 | AE2: 1 | AF2: 1 | AG2: 1 | AH2: 1 | AI2: 1 | AJ2: 1 | AK2: 1 | AL2: 1 | AM2: 1 | AN2: 1 | AO2: 1 | AP2: 1 | AQ2: 1 | AR2: 1 | AS2: 1 | AT2: 1 | AU2: 1 | AV2: 1 | AW2: 1 | AX2: 1 | AY2: 1 | AZ2: 1 | BA2: 1 | BB2: 1 | BC2: 1 | BD2: 1 | BE2: 2 | BF2: 2 | BG2: 2 | BH2: 2 | BI2: 2 | BJ2: 4 | BK2: 4 | BL2: 4 | BM2: 4 | BN2: 4 | BO2: 4 | BP2: 4 | BQ2: 4 | BR2: 4 | BS2: 4 | BT2: 4 | BU2: 32 | BV2: 32 | BW2: 32 | BX2: 32 | BY2: 32
C3: Clase | D3: 0 | E3: +1 | F3: +1 | G3: +1 | H3: +2 | I3: 3 | J3: 0 | K3: 1 | L3: 0 | M3: 0 | N3: 0 | O3: 0 | P3: 0 | Q3: 1 | R3: 1 | S3: 1 | T3: 0 | U3: 0 | V3: 0 | W3: 0 | X3: 1 | Y3: 1 | Z3: 1 | AA3: 3 | AB3: 1 | AC3: 1 | AD3: 1 | AE3: 1 | AF3: 1 | AG3: 1 | AH3: 1 | AI3: 1 | AJ3: 1 | AK3: 1 | AL3: 1 | AM3: 2 | AN3: 1 | AO3: 1 | AP3: 1 | AQ3: 1 | AR3: 1 | AS3: 1 | AT3: 1 | AU3: 1 | AV3: 1 | AW3: 1 | AX3: 1 | AY3: 1 | AZ3: 1 | BA3: 1 | BB3: 1 | BC3: 1 | BD3: 1 | BE3: 1 | BF3: 1 | BG3: 1 | BH3: 1 | BI3: 1 | BJ3: 1 | BK3: 1 | BL3: 1 | BM3: 1 | BN3: 1 | BO3: 1 | BP3: 1 | BQ3: 1 | BR3: 1 | BS3: 1 | BT3: 1 | BU3: 3 | BV3: 3 | BW3: 3 | BX3: 3 | BY3: 3
C4: Origen | D4: 0 | E4: 0 | F4: +1 | G4: +2 | H4: 0 | I4: 0 | J4: 0 | K4: 0 | L4: 0 | M4: +2 | N4: 0 | O4: 1 | P4: 0 | Q4: 0 | R4: 1 | S4: 2 | T4: 0 | U4: 1 | V4: 2 | W4: 0 | X4: 0 | Y4: 1 | Z4: 2 | AA4: 0 | AB4: 1 | AC4: 1 | AD4: 2 | AE4: 1 | AF4: 2 | AG4: 2 | AH4: 2 | AI4: 1 | AJ4: 1 | AK4: 1 | AL4: 2 | AM4: 1 | AN4: 1 | AO4: 1 | AP4: 1 | AQ4: 1 | AR4: 1 | AS4: 1 | AT4: 2 | AU4: 2 | AV4: 1 | AW4: 2 | AX4: 1 | AY4: 1 | AZ4: 1 | BA4: 2 | BB4: 1 | BC4: 2 | BD4: 1 | BE4: 1 | BF4: 1 | BG4: 2 | BH4: 1 | BI4: 1 | BJ4: 1 | BK4: 2 | BL4: 1 | BM4: 1 | BN4: 1 | BO4: 2 | BP4: 2 | BQ4: 1 | BR4: 2 | BS4: 2 | BT4: 2 | BU4: 1 | BV4: 1 | BW4: 1 | BX4: 1 | BY4: 1
C5: Categoría | D5: 0 | E5: 0 | F5: 0 | G5: 0 | H5: 0 | I5: 0 | J5: 0 | K5: 0 | L5: 0 | M5: 0 | N5: 0 | O5: 0 | P5: 0 | Q5: 0 | R5: 0 | S5: 0 | T5: 0 | U5: 0 | V5: 0 | W5: 1 | X5: 1 | Y5: 1 | Z5: 1 | AA5: 0 | AB5: 1 | AC5: 1 | AD5: 1 | AE5: 1 | AF5: 1 | AG5: 1 | AH5: 1 | AI5: 1 | AJ5: 2 | AK5: 2 | AL5: 2 | AM5: 1 | AN5: 2 | AO5: 1 | AP5: 1 | AQ5: 1 | AR5: 1 | AS5: 1 | AT5: 1 | AU5: 1 | AV5: 1 | AW5: 1 | AX5: 1 | AY5: 1 | AZ5: 1 | BA5: 1 | BB5: 1 | BC5: 1 | BD5: 1 | BE5: 4 | BF5: 4 | BG5: 4 | BH5: 4 | BI5: 4 | BJ5: 1 | BK5: 1 | BL5: 1 | BM5: 1 | BN5: 1 | BO5: 1 | BP5: 1 | BQ5: 1 | BR5: 1 | BS5: 1 | BT5: 1 | BU5: 1 | BV5: 1 | BW5: 1 | BX5: 1 | BY5: 1
C6: Código | D6: 0 | E6: 0 | F6: 0 | G6: 0 | H6: 0 | I6: 0 | J6: 0 | K6: 0 | L6: 0 | M6: 0 | N6: 0 | O6: 0 | P6: 0 | Q6: 0 | R6: 0 | S6: 0 | T6: 0 | U6: 0 | V6: 0 | W6: 0 | X6: 0 | Y6: 0 | Z6: 0 | AA6: 0 | AB6: 1 | AC6: 2 | AD6: 6 | AE6: 7 | AF6: 9 | AG6: 12 | AH6: 13 | AI6: 23 | AJ6: 30 | AK6: 39 | AL6: 42 | AM6: 43 | AN6: 49 | AO6: 51 | AP6: 52 | AQ6: 53 | AR6: 54 | AS6: 55 | AT6: 56 | AU6: 57 | AV6: 58 | AW6: 59 | AX6: 60 | AY6: 62 | AZ6: 63 | BA6: 64 | BB6: 65 | BC6: 66 | BD6: 67 | BE6: 11 | BF6: 37 | BG6: 42 | BH6: 48 | BI6: 49 | BJ6: 26 | BK6: 31 | BL6: 46 | BM6: 108 | BN6: 117 | BO6: 118 | BP6: 120 | BQ6: 121 | BR6: 122 | BS6: 123 | BT6: 125 | BU6: 1 | BV6: 2 | BW6: 3 | BX6: 4 | BY6: 5
C7: Gupo | D7: 0 | E7: 0 | F7: 0 | G7: 0 | H7: 0 | I7: 0 | J7: 0 | K7: 0 | L7: +200 | M7: 0 | N7: +100 | O7: 0 | P7: 0 | Q7: 0 | R7: 0 | S7: 0 | T7: 0 | U7: 0 | V7: 0 | W7: 0 | X7: 0 | Y7: 0 | Z7: 0 | AA7: 0 | AB7: 200 | AC7: 200 | AD7: 0 | AE7: 200 | AF7: 0 | AG7: 0 | AH7: 0 | AI7: 200 | AJ7: 200 | AK7: 200 | AL7: 0 | AM7: 100 | AN7: 200 | AO7: 200 | AP7: 200 | AQ7: 200 | AR7: 200 | AS7: 200 | AT7: 0 | AU7: 0 | AV7: 200 | AW7: 0 | AX7: 200 | AY7: 200 | AZ7: 200 | BA7: 0 | BB7: 200 | BC7: 0 | BD7: 200 | BE7: 0 | BF7: 0 | BG7: 0 | BH7: 0 | BI7: 0 | BJ7: 0 | BK7: 0 | BL7: 0 | BM7: 0 | BN7: 0 | BO7: 0 | BP7: 0 | BQ7: 0 | BR7: 0 | BS7: 0 | BT7: 0 | BU7: 0 | BV7: 0 | BW7: 0 | BX7: 0 | BY7: 0
C8: Estado | D8: 0 | E8: 0 | F8: 0 | G8: 0 | H8: 0 | I8: 0 | J8: 0 | K8: 0 | L8: 0 | M8: 0 | N8: 0 | O8: 0 | P8: 0 | Q8: 0 | R8: 0 | S8: 0 | T8: 0 | U8: 0 | V8: 0 | W8: 0 | X8: 0 | Y8: 0 | Z8: 0 | AA8: 0 | AB8: 1 | AC8: 1 | AD8: 1 | AE8: 1 | AF8: 1 | AG8: 1 | AH8: 1 | AI8: 1 | AJ8: 7 | AK8: 7 | AL8: 7 | AM8: 1 | AN8: 7 | AO8: 6 | AP8: 6 | AQ8: 6 | AR8: 6 | AS8: 6 | AT8: 6 | AU8: 6 | AV8: 1 | AW8: 1 | AX8: 1 | AY8: 1 | AZ8: 1 | BA8: 1 | BB8: 1 | BC8: 1 | BD8: 1 | BE8: 1 | BF8: 1 | BG8: 2 | BH8: 2 | BI8: 2 | BJ8: 1 | BK8: 1 | BL8: 6 | BM8: 1 | BN8: 0 | BO8: 0 | BP8: 0 | BQ8: 0 | BR8: 0 | BS8: 0 | BT8: 0 | BU8: 1 | BV8: 1 | BW8: 1 | BX8: 1 | BY8: 1
C9: Delegatura | D9: 0 | E9: 0 | F9: 0 | G9: 0 | H9: 0 | I9: 0 | J9: 0 | K9: 0 | L9: 0 | M9: 0 | N9: 0 | O9: 0 | P9: 0 | Q9: 0 | R9: 0 | S9: 0 | T9: 0 | U9: 0 | V9: 0 | W9: 0 | X9: 0 | Y9: 0 | Z9: 0 | AA9: 0 | AB9: 1 | AC9: 1 | AD9: 1 | AE9: 2 | AF9: 3 | AG9: 3 | AH9: 3 | AI9: 1 | AJ9: 3 | AK9: 2 | AL9: 3 | AM9: 2 | AN9: 1 | AO9: 3 | AP9: 3 | AQ9: 3 | AR9: 3 | AS9: 3 | AT9: 3 | AU9: 3 | AV9: 3 | AW9: 1 | AX9: 1 | AY9: 1 | AZ9: 1 | BA9: 1 | BB9: 1 | BC9: 1 | BD9: 1 | BE9: 1 | BF9: 2 | BG9: 0 | BH9: 0 | BI9: 0 | BJ9: 2 | BK9: 3 | BL9: 1 | BM9: 2 | BN9: 3 | BO9: 3 | BP9: 3 | BQ9: 3 | BR9: 3 | BS9: 3 | BT9: 3 | BU9: 1 | BV9: 3 | BW9: 2 | BX9: 2 | BY9: 3
C10: Director Técnico | D10: 0 | E10: 0 | F10: 0 | G10: 0 | H10: 0 | I10: 0 | J10: 0 | K10: 0 | L10: 0 | M10: 0 | N10: 0 | O10: 0 | P10: 0 | Q10: 0 | R10: 0 | S10: 0 | T10: 0 | U10: 0 | V10: 0 | W10: 0 | X10: 0 | Y10: 0 | Z10: 0 | AA10: 0 | AB10: 0 | AC10: 0 | AD10: 0 | AE10: 0 | AF10: 0 | AG10: 0 | AH10: 0 | AI10: 0 | AJ10: 0 | AK10: 0 | AL10: 0 | AM10: 0 | AN10: 0 | AO10: 0 | AP10: 0 | AQ10: 0 | AR10: 0 | AS10: 0 | AT10: 0 | AU10: 0 | AV10: 0 | AW10: 0 | AX10: 0 | AY10: 0 | AZ10: 0 | BA10: 0 | BB10: 0 | BC10: 0 | BD10: 0 | BE10: 0 | BF10: 0 | BG10: 0 | BH10: 0 | BI10: 0 | BJ10: 0 | BK10: 0 | BL10: 0 | BM10: 0 | BN10: 0 | BO10: 0 | BP10: 0 | BQ10: 0 | BR10: 0 | BS10: 0 | BT10: 0 | BU10: 300 | BV10: 300 | BW10: 300 | BX10: 300 | BY10: 300
C11: Nombre de la entidad | D11: Total Entidades Establecimientos de crédito sin IOE'S | E11: Total Sector Privado | F11: Total Sector Privado Nacional | G11: Total Sector Privado Extranjero | H11: Total Sector Público | I11: Total Sector Cooperativas | J11: Total Bancos | K11: Bancos Privados | L11: Bancos Privados Nacionales | M11: Bancos Privados Extranjeros | N11: Bancos Públicos | O11: Bancos Nacionales | P11: Total CFIs | Q11: CFIs Privadas | R11: CFIs Privadas Nacionales | S11: CFIs Privadas Extranjeras | T11: Total CFs | U11: Total CFs Nacionales (Tradicionales+Leasing) | V11: Total CFs Extranjeras (Tradicionales+Leasing) | W11: Total CFs Tradicionales | X11: CFs Privadas | Y11: CFs Privadas Nacionales | Z11: CFs Privadas Extranjeras | AA11: Total Cooperativas | AB11: BANCO DE BOGOTA | AC11: BANCO POPULAR | AD11: ITAÚ CORPBANCA COLOMBIA S.A. | AE11: BANCOLOMBIA | AF11: CITIBANK-COLOMBIA | AG11: GNB SUDAMERIS | AH11: BBVA COLOMBIA | AI11: OCCIDENTE | AJ11: BANCO CAJA SOCIAL | AK11: DAVIVIENDA | AL11: SCOTIABANK COLPATRIA S.A | AM11: BANAGRARIO | AN11: BANCO AV VILLAS | AO11: BANCO CREDIFINANCIERA | AP11: BANCAMIA | AQ11: BANCO W S.A. | AR11: BANCOOMEVA | AS11: BANCO FINANDINA | AT11: BANCO FALABELLA S.A. | AU11: BANCO PICHINCHA S.A. | AV11: COOPCENTRAL | AW11: BANCO SANTANDER DE NEGOCIOS COLOMBIA | AX11: BANCO MUNDO MUJER S.A. | AY11: MIBANCO S.A. | AZ11: BANCO SERFINANZA S.A. | BA11: BANCO J.P: MORGAN COLOMBIA S.A. | BB11: LULO BANK S.A. | BC11: BANCO BTG PACTUAL | BD11: BANCO UNION | BE11: CORFICOLOMBIANA | BF11: B INV BANCOLOMBIA | BG11: BNP PARIBAS COLOMBIA | BH11: CORPORACIÓN FINANCIERA GNB SUDAMERIS S.A | BI11: CORPORACIÓN FINANCIERA DAVIVIENDA | BJ11: COMPAÑÍA DE FINANCIAMIENTO TUYA | BK11: GM FINANCIAL COLOMBIA S.A. | BL11: COLTEFINANCIERA | BM11: IRIS CF | BN11: CREDIFAMILIA | BO11: CREZCAMOS S.A. | BP11: LA HIPOTECARIA | BQ11: FINANCIERA JURISCOOP S.A. | BR11: RCI COLOMBIA S.A. | BS11: BANCAR TECNOLOGIA CO S.A. | BT11: SANTANDER CONSUMER S.A. C.F.C | BU11: COOP FINAN DE ANTIOQUIA | BV11: JFK COOPERATIVA FINANCIERA | BW11: COOP FINAN COOFINEP | BX11: COOP FINAN COTRAFA | BY11: COOP FINAN CONFIAR
C12: Cifras con corte a 01-feb-2023 | D12: dic-22 | E12: dic-22 | F12: dic-22 | G12: dic-22 | H12: dic-22 | I12: dic-22 | J12: dic-22 | K12: dic-22 | L12: dic-22 | M12: dic-22 | N12: dic-22 | O12: dic-22 | P12: dic-22 | Q12: dic-22 | R12: dic-22 | S12: dic-22 | T12: dic-22 | U12: dic-22 | V12: dic-22 | W12: dic-22 | X12: dic-22 | Y12: dic-22 | Z12: dic-22 | AA12: dic-22 | AB12: dic-22 | AC12: dic-22 | AD12: dic-22 | AE12: dic-22 | AF12: dic-22 | AG12: dic-22 | AH12: dic-22 | AI12: dic-22 | AJ12: dic-22 | AK12: dic-22 | AL12: dic-22 | AM12: dic-22 | AN12: dic-22 | AO12: dic-22 | AP12: dic-22 | AQ12: dic-22 | AR12: dic-22 | AS12: dic-22 | AT12: dic-22 | AU12: dic-22 | AV12: dic-22 | AW12: dic-22 | AX12: dic-22 | AY12: dic-22 | AZ12: dic-22 | BA12: dic-22 | BB12: dic-22 | BC12: dic-22 | BD12: dic-22 | BE12: dic-22 | BF12: dic-22 | BG12: dic-22 | BH12: dic-22 | BI12: dic-22 | BJ12: dic-22 | BK12: dic-22 | BL12: dic-22 | BM12: dic-22 | BN12: dic-22 | BO12: dic-22 | BP12: dic-22 | BQ12: dic-22 | BR12: dic-22 | BS12: dic-22 | BT12: dic-22 | BU12: dic-22 | BV12: dic-22 | BW12: dic-22 | BX12: dic-22 | BY12: dic-22
A13: BALANCE (cifras en $ millones)
A14: ACTIVOS | D14: 9.7296518e+08 | E14: 9.3421939e+08 | F14: 6.8139182e+08 | G14: 2.5282757e+08 | H14: 33933046 | I14: 4812741.5 | J14: 9.2412105e+08 | K14: 8.9018801e+08 | L14: 6.4523797e+08 | M14: 2.4495003e+08 | N14: 33933046 | O14: 6.7917102e+08 | P14: 27525820 | Q14: 27525820 | R14: 27161044 | S14: 364775.9 | T14: 16505562 | U14: 8992802.7 | V14: 7512759.1 | W14: 16505562 | X14: 16505562 | Y14: 8992802.7 | Z14: 7512759.1 | AA14: 4812741.5 | AB14: 1.1035704e+08 | AC14: 32567740 | AD14: 28861832 | AE14: 2.4576572e+08 | AF14: 13619573 | AG14: 36757106 | AH14: 99238481 | AI14: 54637784 | AJ14: 19621760 | AK14: 1.3722038e+08 | AL14: 43190425 | AM14: 33933046 | AN14: 19420816 | AO14: 2238576.4 | AP14: 2257602.7 | AQ14: 2143375.7 | AR14: 4995411.7 | AS14: 3652847.8 | AT14: 7721628.9 | AU14: 3036406.3 | AV14: 1344272 | AW14: 7567597.5 | AX14: 3078571.7 | AY14: 1930366.7 | AZ14: 2553359.2 | BA14: 4220039.6 | BB14: 450075.58 | BC14: 736942.9 | BD14: 1002268.1 | BE14: 23473166 | BF14: 2119015.8 | BG14: 364775.9 | BH14: 1150659.7 | BI14: 418203.03 | BJ14: 5035508.6 | BK14: 2675528.2 | BL14: 1282273.4 | BM14: 621741.13 | BN14: 663574.21 | BO14: 401664.22 | BP14: 415006.95 | BQ14: 1389705.4 | BR14: 3868208.2 | BS14: 36692.72 | BT14: 115658.91 | BU14: 542945.38 | BV14: 1464108.6 | BW14: 349610.59 | BX14: 1090780.1 | BY14: 1365296.8
B15: DISPONIBLE | D15: 62457690 | E15: 60567309 | F15: 39129063 | G15: 21438245 | H15: 1429664.9 | I15: 460716.5 | J15: 58321487 | K15: 56891822 | L15: 35947035 | M15: 20944787 | N15: 1429664.9 | O15: 37376700 | P15: 2329704.5 | Q15: 2329704.5 | R15: 2311230.8 | S15: 18473.72 | T15: 1345782.1 | U15: 870797.16 | V15: 474984.98 | W15: 1345782.1 | X15: 1345782.1 | Y15: 870797.16 | Z15: 474984.98 | AA15: 460716.5 | AB15: 6396893 | AC15: 1709214.2 | AD15: 1507589.8 | AE15: 13066341 | AF15: 1436429.1 | AG15: 4322634.6 | AH15: 9375035.2 | AI15: 2651625.3 | AJ15: 1071993.7 | AK15: 7698210.1 | AL15: 2946243.2 | AM15: 1429664.9 | AN15: 869833.57 | AO15: 282986.95 | AP15: 152121.64 | AQ15: 204952.03 | AR15: 342159.28 | AS15: 223181.14 | AT15: 274574.07 | AU15: 161741.44 | AV15: 234660.62 | AW15: 590131.66 | AX15: 281088.32 | AY15: 222423.25 | AZ15: 316735.2 | BA15: 8107.94 | BB15: 85861.22 | BC15: 322299.67 | BD15: 136754.62 | BE15: 1858766.6 | BF15: 398687.86 | BG15: 18473.72 | BH15: 35306.73 | BI15: 18469.58 | BJ15: 523835.38 | BK15: 104454 | BL15: 82531.28 | BM15: 82376.91 | BN15: 62149.71 | BO15: 15670.63 | BP15: 51177.6 | BQ15: 119903.88 | BR15: 179914.9 | BS15: 14046.82 | BT15: 109721.03 | BU15: 69470.38 | BV15: 163305.98 | BW15: 39710.72 | BX15: 86565.62 | BY15: 101663.8
B16: POSICIONES ACTIVAS EN OPERACIONES DE MERCADO MONETARIO Y RELACIONADAS | D16: 21768179 | E16: 21497472 | F16: 10008920 | G16: 11488552 | H16: 270706.68 | I16: 0 | J16: 21450493 | K16: 21179786 | L16: 9759143.4 | M16: 11420643 | N16: 270706.68 | O16: 10029850 | P16: 317661.85 | Q16: 317661.85 | R16: 249752.87 | S16: 67908.98 | T16: 23.64 | U16: 23.64 | V16: 0 | W16: 23.64 | X16: 23.64 | Y16: 23.64 | Z16: 0 | AA16: 0 | AB16: 4450600.6 | AC16: 9091.28 | AD16: 668504.59 | AE16: 3167463 | AF16: 897664.42 | AG16: 6853173.2 | AH16: 899080.68 | AI16: 976218.83 | AJ16: 620520.22 | AK16: 416488.48 | AL16: 514651.84 | AM16: 270706.68 | AN16: 47127.19 | AO16: 0 | AP16: 12007.43 | AQ16: 22592.75 | AR16: 34030.88 | AS16: 0 | AT16: 0 | AU16: 14656.52 | AV16: 0 | AW16: 455336.9 | AX16: 0 | AY16: 3002.78 | AZ16: 0 | BA16: 1117575 | BB16: 0 | BC16: 0 | BD16: 0 | BE16: 249752.87 | BF16: 0 | BG16: 67908.98 | BH16: 0 | BI16: 0 | BJ16: 23.64 | BK16: 0 | BL16: 0 | BM16: 0 | BN16: 0 | BO16: 0 | BP16: 0 | BQ16: 0 | BR16: 0 | BS16: 0 | BT16: 0 | BU16: 0 | BV16: 0 | BW16: 0 | BX16: 0 | BY16: 0
C17: INTERBANCARIOS | D17: 2176542.1 | E17: 2096417.8 | F17: 1423374.8 | G17: 673043.01 | H17: 80124.33 | I17: 0 | J17: 2114822.4 | K17: 2034698.1 | L17: 1374667.2 | M17: 660030.94 | N17: 80124.33 | O17: 1454791.5 | P17: 61696.02 | Q17: 61696.02 | R17: 48683.95 | S17: 13012.07 | T17: 23.64 | U17: 23.64 | V17: 0 | W17: 23.64 | X17: 23.64 | Y17: 23.64 | Z17: 0 | AA17: 0 | AB17: 170159.34 | AC17: 9091.28 | AD17: 117844.97 | AE17: 350515.23 | AF17: 0 | AG17: 330620.17 | AH17: 120167.19 | AI17: 209370.9 | AJ17: 620520.22 | AK17: 0 | AL17: 0 | AM17: 80124.33 | AN17: 0 | AO17: 0 | AP17: 12007.43 | AQ17: 0 | AR17: 0 | AS17: 0 | AT17: 0 | AU17: 0 | AV17: 0 | AW17: 91398.61 | AX17: 0 | AY17: 3002.78 | AZ17: 0 | BA17: 0 | BB17: 0 | BC17: 0 | BD17: 0 | BE17: 48683.95 | BF17: 0 | BG17: 13012.07 | BH17: 0 | BI17: 0 | BJ17: 23.64 | BK17: 0 | BL17: 0 | BM17: 0 | BN17: 0 | BO17: 0 | BP17: 0 | BQ17: 0 | BR17: 0 | BS17: 0 | BT17: 0 | BU17: 0 | BV17: 0 | BW17: 0 | BX17: 0 | BY17: 0
C18: OPERACIONES DE REPORTO O REPO | D18: 35271.51 | E18: 35271.51 | F18: 35271.51 | G18: 0 | H18: 0 | I18: 0 | J18: 35271.51 | K18: 35271.51 | L18: 35271.51 | M18: 0 | N18: 0 | O18: 35271.51 | P18: 0 | Q18: 0 | R18: 0 | S18: 0 | T18: 0 | U18: 0 | V18: 0 | W18: 0 | X18: 0 | Y18: 0 | Z18: 0 | AA18: 0 | AB18: 0 | AC18: 0 | AD18: 0 | AE18: 35271.51 | AF18: 0 | AG18: 0 | AH18: 0 | AI18: 0 | AJ18: 0 | AK18: 0 | AL18: 0 | AM18: 0 | AN18: 0 | AO18: 0 | AP18: 0 | AQ18: 0 | AR18: 0 | AS18: 0 | AT18: 0 | AU18: 0 | AV18: 0 | AW18: 0 | AX18: 0 | AY18: 0 | AZ18: 0 | BA18: 0 | BB18: 0 | BC18: 0 | BD18: 0 | BE18: 0 | BF18: 0 | BG18: 0 | BH18: 0 | BI18: 0 | BJ18: 0 | BK18: 0 | BL18: 0 | BM18: 0 | BN18: 0 | BO18: 0 | BP18: 0 | BQ18: 0 | BR18: 0 | BS18: 0 | BT18: 0 | BU18: 0 | BV18: 0 | BW18: 0 | BX18: 0 | BY18: 0
C19: OPERACIONES SIMULTÁNEAS | D19: 19281282 | E19: 19090699 | F19: 8550273.7 | G19: 10540426 | H19: 190582.35 | I19: 0 | J19: 19025316 | K19: 18834733 | L19: 8349204.7 | M19: 10485529 | N19: 190582.35 | O19: 8539787.1 | P19: 255965.83 | Q19: 255965.83 | R19: 201068.92 | S19: 54896.91 | T19: 0 | U19: 0 | V19: 0 | W19: 0 | X19: 0 | Y19: 0 | Z19: 0 | AA19: 0 | AB19: 4280441.3 | AC19: 0 | AD19: 550659.62 | AE19: 2781676.2 | AF19: 897664.42 | AG19: 6522553 | AH19: 778913.49 | AI19: 766847.94 | AJ19: 0 | AK19: 416488.48 | AL19: 514651.84 | AM19: 190582.35 | AN19: 47127.19 | AO19: 0 | AP19: 0 | AQ19: 22592.75 | AR19: 34030.88 | AS19: 0 | AT19: 0 | AU19: 14656.52 | AV19: 0 | AW19: 363938.29 | AX19: 0 | AY19: 0 | AZ19: 0 | BA19: 842491.57 | BB19: 0 | BC19: 0 | BD19: 0 | BE19: 201068.92 | BF19: 0 | BG19: 54896.91 | BH19: 0 | BI19: 0 | BJ19: 0 | BK19: 0 | BL19: 0 | BM19: 0 | BN19: 0 | BO19: 0 | BP19: 0 | BQ19: 0 | BR19: 0 | BS19: 0 | BT19: 0 | BU19: 0 | BV19: 0 | BW19: 0 | BX19: 0 | BY19: 0
C20: OPERACIONES DE TRANSFERENCIA TEMPORAL DE VALORES | D20: 275083.4 | E20: 275083.4 | F20: 0 | G20: 275083.4 | H20: 0 | I20: 0 | J20: 275083.4 | K20: 275083.4 | L20: 0 | M20: 275083.4 | N20: 0 | O20: 0 | P20: 0 | Q20: 0 | R20: 0 | S20: 0 | T20: 0 | U20: 0 | V20: 0 | W20: 0 | X20: 0 | Y20: 0 | Z20: 0 | AA20: 0 | AB20: 0 | AC20: 0 | AD20: 0 | AE20: 0 | AF20: 0 | AG20: 0 | AH20: 0 | AI20: 0 | AJ20: 0 | AK20: 0 | AL20: 0 | AM20: 0 | AN20: 0 | AO20: 0 | AP20: 0 | AQ20: 0 | AR20: 0 | AS20: 0 | AT20: 0 | AU20: 0 | AV20: 0 | AW20: 0 | AX20: 0 | AY20: 0 | AZ20: 0 | BA20: 275083.4 | BB20: 0 | BC20: 0 | BD20: 0 | BE20: 0 | BF20: 0 | BG20: 0 | BH20: 0 | BI20: 0 | BJ20: 0 | BK20: 0 | BL20: 0 | BM20: 0 | BN20: 0 | BO20: 0 | BP20: 0 | BQ20: 0 | BR20: 0 | BS20: 0 | BT20: 0 | BU20: 0 | BV20: 0 | BW20: 0 | BX20: 0 | BY20: 0
C21: OTRAS POSICIONES ACTIVAS EN OPERACIONES DE MERCADO MONETARIO | D21: -0.02 | E21: -0.02 | F21: -0.0099999998 | G21: -0.0099999979 | H21: 0 | I21: 0 | J21: -0.020000003 | K21: -0.02 | L21: -0.0099999998 | M21: -0.0099999979 | N21: 0 | O21: -0.0099999998 | P21: 0 | Q21: 0 | R21: 0 | S21: 0 | T21: 0 | U21: 0 | V21: 0 | W21: 0 | X21: 0 | Y21: 0 | Z21: 0 | AA21: 0 | AB21: 0 | AC21: 0 | AD21: 0 | AE21: 0 | AF21: 0 | AG21: -0.0099999998 | AH21: 0 | AI21: -0.01 | AJ21: 0 | AK21: 0 | AL21: 0 | AM21: 0 | AN21: 0 | AO21: 0 | AP21: 0 | AQ21: 0 | AR21: 0 | AS21: 0 | AT21: 0 | AU21: 0 | AV21: 0 | AW21: 0 | AX21: 0 | AY21: 0 | AZ21: 0 | BA21: 0 | BB21: 0 | BC21: 0 | BD21: 0 | BE21: 0 | BF21: 0 | BG21: 0 | BH21: 0 | BI21: 0 | BJ21: 0 | BK21: 0 | BL21: 0 | BM21: 0 | BN21: 0 | BO21: 0 | BP21: 0 | BQ21: 0 | BR21: 0 | BS21: 0 | BT21: 0 | BU21: 0 | BV21: 0 | BW21: 0 | BX21: 0 | BY21: 0
